Workbook

Sheet 3月加热汇总
A1: 发布日期 | B1: 投放截止日期 | C1: 状态 | D1: 达人名称 | E1: 链接 | F1: 投放记录 xx日投放xx元 | G1: 标题 | H1: 投前互动量 | I1: 投放互动量 | J1: 总互动量 | K1: 总投放金额 | L1: 综合cpe *投入/笔记外层互动数据 | M1: 一级分类 | N1: 二级分类 | O1: 备注 | P1: 最终互动量 | Q1: 爆款定级
A2: 汇总 | H2: - | I2: - | J2: =SUM(J3:J99) | K2: =SUM(K3:K99) | L2: =K2/J2 | P2: =SUM(P3:P98)
A3: 46082 | B3: =A3+7 | C3: 投放完毕 | D3: 酸奶吐司 | E3: https://www.douyin.com/video/7612207816275352497 | F3: 2026/3/2投放500元 2026/3/3投放1000元2026/3/4投放500元2026/3/5投放500元2026/3/9投放500元 | G3: 广州的滴滴车也太可爱了吧！坐得心情都美美的#广州 #广州滴滴 | H3: 112 | I3: ='详细数据'!AC2+'详细数据'!AC16+'详细数据'!AC20+'详细数据'!AC26+'详细数据'!AC38 | J3: 37471 | K3: =1000+500+500+'详细数据'!J26+'详细数据'!J38 | L3: =K3/J3 | M3: 车内 | N3: 车内整洁 | P3: 37471 | Q3: =IF(J3="","",IF(J3>=500000,"S 级",IF(J3>=100000,"A 级",IF(J3>=50000,"B 级","C 级"))))
A4: 46081 | B4: =A4+7 | C4: 投放完毕 | D4: 尚雅求真 | E4: https://www.douyin.com/video/7611743676641705295 | F4: 2026/3/2投放500元 | G4: “滴滴”赞 | H4: 74 | I4: 1094 | J4: 1204 | K4: 500 | L4: =K4/J4 | M4: 地广/活动 | N4: 品牌 | P4: 1204 | Q4: =IF(J4="","",IF(J4>=500000,"S 级",IF(J4>=100000,"A 级",IF(J4>=50000,"B 级","C 级"))))
A5: 46082 | B5: =A5+7 | C5: 投放完毕 | D5: Mr钟又离 | E5: https://www.douyin.com/video/7612244922887857787 | F5: 2026/3/2投放500元 2026/3/3投放1000元 | G5: 太酷了 男滴滴司机的公主车： 啥样生活都是经营出来的不是吗#温暖治愈 #人间烟火#滴滴司机 #非标准人生#清醒的选负责到底 | H5: 128 | I5: =1427+'详细数据'!AC14 | J5: 5167 | K5: 1500 | L5: =K5/J5 | M5: 车内 | N5: 特殊车型/车衣 | P5: 5167 | Q5: =IF(J5="","",IF(J5>=500000,"S 级",IF(J5>=100000,"A 级",IF(J5>=50000,"B 级","C 级"))))
A6: 46082 | B6: =A6+7 | C6: 投放完毕 | D6: 白开水泡茶 | E6: https://www.douyin.com/note/7612110532075037129 | F6: 2026/3/2投放500元 2026/3/3投放1000元 | G6: 武汉下雨天，我打了辆滴滴准备回学校。 | H6: 909 | I6: =1280+'详细数据'!AC13 | J6: 5887 | K6: 1500 | L6: =K6/J6 | M6: 场景 | N6: 通勤上下班 | P6: 5887 | Q6: =IF(J6="","",IF(J6>=500000,"S 级",IF(J6>=100000,"A 级",IF(J6>=50000,"B 级","C 级"))))
A7: 46082 | B7: =A7+7 | C7: 投放完毕 | D7: 清风✨ | E7: https://www.douyin.com/video/7612087271226903844 | F7: 2026/3/2投放500元 2026/3/3投放1000元2026/3/4投放500元2026/3/5投放500元2026/3/9投放500元 | G7: 小同志，磁场又弱了吧，是时候充电了 #天安门 #士兵突击 #滴滴司机 感谢北京的滴滴师傅，放慢车速让我们看天安门夜景 | H7: 1056 | I7: =2871+'详细数据'!AC12+'详细数据'!AC21+'详细数据'!AC31+'详细数据'!AC37 | J7: 36628 | K7: =1000+500+500+'详细数据'!J31+'详细数据'!J37 | L7: =K7/J7 | M7: 司机 | N7: 司机服务 | P7: 36628 | Q7: =IF(J7="","",IF(J7>=500000,"S 级",IF(J7>=100000,"A 级",IF(J7>=50000,"B 级","C 级"))))
A8: 46081 | B8: =A8+7 | C8: 投放完毕 | D8: 北辰 | E8: https://www.douyin.com/note/7611832044951303909 | F8: 2026/3/2投放500元 | G8: 第2集 | 爱心：爱的传递。这是我遇见的最暖心的滴滴司机师傅，太原的成师傅， | H8: 99 | I8: 1073 | J8: 1222 | K8: 500 | L8: =K8/J8 | M8: 司机 | N8: 司乘温暖 | P8: 1222 | Q8: =IF(J8="","",IF(J8>=500000,"S 级",IF(J8>=100000,"A 级",IF(J8>=50000,"B 级","C 级"))))
A9: 46080 | B9: =A9+7 | C9: 投放完毕 | D9: 一生有你 | E9: https://www.douyin.com/note/7611432494563328113 | F9: 2026/3/2投放500元 2026/3/3投放1000元2026/3/4投放500元 | G9: 人生第一次打到滴滴女司机，技术稳得一批，完全不输男司机👍 | H9: 985 | I9: =1292+'详细数据'!AC15+'详细数据'!AC19 | J9: 8264 | K9: =1000+500+500 | L9: =K9/J9 | M9: 司机 | N9: 女司机 | P9: 8264 | Q9: =IF(J9="","",IF(J9>=500000,"S 级",IF(J9>=100000,"A 级",IF(J9>=50000,"B 级","C 级"))))
A10: 46080 | B10: =A10+7 | C10: 投放完毕 | D10: Saffron | E10: https://www.douyin.com/note/7611499522330631857 | F10: 2026/3/2投放500元 2026/3/3投放1000元2026/3/4投放500元 | G10: 下班遇到了一位温暖的滴滴司机，椅背贴了一张纸条，口袋里放了两本小册子，两支笔和一面镜子 | H10: 261 | I10: =1301+'详细数据'!AC11+'详细数据'!AC22 | J10: 7509 | K10: =1000+500+500 | L10: =K10/J10 | M10: 车内 | N10: 司机自发装置 | P10: 7509 | Q10: =IF(J10="","",IF(J10>=500000,"S 级",IF(J10>=100000,"A 级",IF(J10>=50000,"B 级","C 级"))))
A11: 46079 | B11: =A11+7 | C11: 投放完毕 | D11: 康老师(武汉少儿阅读) | E11: https://www.douyin.com/video/7611192244423229139 | F11: 2026/3/2投放500元 | G11: 武汉有滴滴公交啦！学名响应式公交 | H11: 147 | I11: 1145 | J11: 1371 | K11: 500 | L11: =K11/J11 | M11: 产品力 | N11: 网约公交 | P11: 1371 | Q11: =IF(J11="","",IF(J11>=500000,"S 级",IF(J11>=100000,"A 级",IF(J11>=50000,"B 级","C 级"))))
A12: 46079 | B12: =A12+7 | C12: 投放完毕 | D12: 馬壹榴·我是眠眠呀 | E12: https://www.douyin.com/video/7611742459936919402 | F12: 2026/3/3投放500元 | G12: 今天打车遇到一个很有童趣的师傅，哈哈！#滴滴 #滴滴司机 #滴滴打车 | H12: 71 | I12: ='详细数据'!AC18 | J12: 282 | K12: 500 | L12: =K12/J12 | M12: 司机 | N12: 司乘互动 | P12: 282 | Q12: =IF(J12="","",IF(J12>=500000,"S 级",IF(J12>=100000,"A 级",IF(J12>=50000,"B 级","C 级"))))
A13: 46083 | B13: =A13+7 | C13: 投放完毕 | D13: 小红碎花裤衩儿 | E13: https://www.douyin.com/video/7612686487277578602 | F13: 2026/3/3投放500元2026/3/4投放500元 | G13: 第30集 | 这马师傅上车给我俩整蒙了，太有活儿了，威海rapper #威海旅游 #滴滴司机 #威海马大帅 #加油奥利给 #马年说马 | H13: 93 | I13: ='详细数据'!AC17+'详细数据'!AC23 | J13: 4251 | K13: =500+500 | L13: =K13/J13 | M13: 司机 | N13: 司乘互动 | P13: 4251 | Q13: =IF(J13="","",IF(J13>=500000,"S 级",IF(J13>=100000,"A 级",IF(J13>=50000,"B 级","C 级"))))
A14: 46084 | B14: =A14+7 | C14: 投放完毕 | D14: 一場、流★雨 | E14: https://www.douyin.com/video/7612918993481033330 | F14: 2026/3/4投放500元 | G14: 这辈子第一次坐RR，居然是在滴滴订单里😂😂 | H14: 90 | I14: ='详细数据'!AC25 | J14: 2159 | K14: 500 | L14: =K14/J14 | M14: 产品力 | N14: 专车/豪华车 | P14: 2159 | Q14: =IF(J14="","",IF(J14>=500000,"S 级",IF(J14>=100000,"A 级",IF(J14>=50000,"B 级","C 级"))))
B15: =A15+7 | C15: 无法投放 | D15: 娜L. | E15: https://www.douyin.com/video/7612865593025511337 | F15: 2026/3/4投放500元 | G15: 这是一段很酷也非常有意义的事情！刚到北京那年，本想着去找一辆自行车夜骑天安门，搜索了附近离我们最近的自行车停放点，但是路程太远，最终还是没有夜骑上。后面就打了一辆滴滴车，司机师傅人超级好，首先问我们赶时间吗？然后就带我们绕路经过天安门，到了天安门车速给我们放慢啦，还往里开了一点，好让我们拍视频，还让我们多拍几个做纪念，因为不知道我们下一次来北京是什么时候啦。#天安门夜景 #人活着不就为了这几个瞬间 #祖国万岁 #世界和平 #北京滴滴司机 | H15: 108 | I15: 0 | K15: 0 | L15: =K15/J15 | M15: 司机
A16: 46084 | B16: =A16+7 | C16: 投放完毕 | D16: 萌萌小🌧 | E16: https://www.douyin.com/note/7613031533112581883 | F16: 2026/3/4投放500元 | G16: 这次对新疆体验感很特殊，飞机上一起坐的大哥他是来工作听说我自己来跟我说这边的有趣的地方，他说在快到新疆的景色更美，靠近新疆时雪山真的很美，下飞机后打车滴滴司机里元宵快乐，欢迎来新疆过节，他看我自己来跟我说很多需要注意的事情，晚上很晚到酒店里后保洁阿姨跟我笑着那种是善意的笑，她说话像中部地区的，江西那边口音不像本地人，跟我说房间在哪里哪里，我没太热情回应，出来吃晚饭时听司机说有家挺好吃的，我就去了，后面老板看我说话有点像外地，就问我来旅游的吗，自己吃饭，我说从安徽过来的，想看看新疆的美景，他就跟我说这边很多好玩的，希望喜欢这里，他在上菜时端过来一碟我没点的，他说这是送的自己做的，马肠包马肉凉菜，后面结账时我问马肉价格这边多少他说136，怪不得天上龙肉地上马肉，今天上午我点了天润的奶制品想带回去，外卖共100多，那个外卖里送了罐干噎酸奶，下午想自驾去天山天池看夕阳可天气还是雾蒙蒙，山里估计视野不太好，这边8.9点太阳下山，我担心我车技回来不行就改去和田二街好好尝尝这边吃的，滴滴司机我问他国道和山路好不好走，他说可以走，于是我准备改计划订车出发，司机就问了我是外地哪里的我说安徽的，他说我真厉害自己敢来这么远，后来他给我送到地址时跟我说前面有点堵，让我等一会下他给我送到小吃街里，于是我下车便是美食一条路，他说新疆本地人几乎很多都走不出省，对外面的世界同样充满好奇期待，他准备等孩子暑假也去外面玩玩，买烤馕时那两个维吾尔族的男生结账我问他多少钱，他说一个馕5元，我共4个馕和2个小馕，他俩说着听不懂的话最后说23，我说好，付过去了，确定哈，他俩交流两句说对，然后我去餐厅最后尝一下这里的菜，那几道菜加烧烤共126，服务员是个同龄的少数名族女孩很好看，她一直跟我说少点一点哦，吃不完的，我说好，后面上菜时阿姨说我一个人吗，我说嗯，过一会刚刚小姑娘过来给我一碗甜的牛奶和白砂糖，她说当地的奶皮子配糖吃会好很多，单吃的话会很酸，她注意到我在外面买的奶皮子了哈哈，后面我要真空打包带走，老板娘叫两个人过来帮忙包装，我问她打包费多少，她说不用，吃完回酒店时我想明晚的航班9点，我2点退房后面去机场有点早想要么再定一晚，到前台我想了下跟前台说房间续2个小时吧，续到4点，明晚飞机9点，机场很大我提前几小时到正好不值当续订，酒店续时30一小时，一晚160多我那个房间，前台有个姐姐说不用了，我结束给个好评就好，还有没有其他的需要的，我说房间的拖鞋需要一个新的，当我回房间后发现房间在我6点走后被人又打扫了一遍，而今天下午4点阿姨过来过一次给我洗漱用品了，现在的房间里开着的窗户被关上，水多给了2瓶共4瓶，我开着的面包袋子被系好，睡衣也被叠好了#新疆 #新疆是个好地方 #乌鲁木齐 #抖音美食推荐官 #热点小助手 @抖音小助手 | H16: 199 | I16: ='详细数据'!AC24 | J16: 1870 | K16: 500 | L16: =K16/J16 | M16: 场景 | N16: 旅游出行 | P16: 1870 | Q16: =IF(J16="","",IF(J16>=500000,"S 级",IF(J16>=100000,"A 级",IF(J16>=50000,"B 级","C 级"))))
A17: 46085 | B17: =A17+7 | C17: 投放完毕 | D17: 小万不吃香菜 | E17: https://www.douyin.com/video/7613215289803536101 | F17: 2026/3/5投放500元2026/3/9投放500元 | G17: 打到了一辆超级干净的滴滴心情都变美了#打车打车 | H17: 91 | I17: ='详细数据'!AC27+'详细数据'!AC36 | J17: 3769 | K17: =500+'详细数据'!J36 | L17: =K17/J17 | M17: 车内 | N17: 车内整洁 | P17: 3769 | Q17: =IF(J17="","",IF(J17>=500000,"S 级",IF(J17>=100000,"A 级",IF(J17>=50000,"B 级","C 级"))))
A18: 46086 | B18: =A18+7 | C18: 投放完毕 | D18: 🦁🦁奔跑的蜗牛 | E18: https://www.douyin.com/note/7613350700244157626 | F18: 2026/3/5投放500元 | G18: 今天出门打车居然打到了特斯拉，北京果然藏龙卧虎啊，连特斯拉都来跑滴滴了#特斯拉 #特斯拉汽车 #北京网约车 #北京网约车司机 | H18: 155 | I18: ='详细数据'!AC29 | J18: 1556 | K18: 500 | L18: =K18/J18 | M18: 车内 | N18: 特殊车型/车衣 | P18: 1556 | Q18: =IF(J18="","",IF(J18>=500000,"S 级",IF(J18>=100000,"A 级",IF(J18>=50000,"B 级","C 级"))))
A19: 46082 | B19: =A19+7 | C19: 投放完毕 | D19: 花渐落 | E19: https://www.douyin.com/note/7612219889386191970 | F19: 2026/3/5投放500元 | G19: 郑州今后的发展会越来越好： | H19: 71 | I19: ='详细数据'!AC28 | J19: 1558 | K19: 500 | L19: =K19/J19 | M19: 无匹配类别 | N19: 无匹配类别 | P19: 1558 | Q19: =IF(J19="","",IF(J19>=500000,"S 级",IF(J19>=100000,"A 级",IF(J19>=50000,"B 级","C 级"))))
A20: 46085 | B20: =A20+7 | C20: 投放完毕 | D20: 小万不吃香菜 | E20: https://www.douyin.com/video/7613215289803536101 | F20: 2026/3/5投放500元 | G20: 打到了一辆超级干净的滴滴心情都变美了#打车打车 | H20: 106 | I20: ='详细数据'!AC30 | J20: 3485 | K20: 500 | L20: =K20/J20 | M20: 车内 | N20: 车内整洁 | P20: 3485 | Q20: =IF(J20="","",IF(J20>=500000,"S 级",IF(J20>=100000,"A 级",IF(J20>=50000,"B 级","C 级"))))
A21: 46086 | B21: =A21+7 | C21: 投放完毕 | D21: GOOD. | E21: https://www.douyin.com/note/7613787027502461352 | F21: 2026/3/9投放500元2026/3/12投放500元 | G21: 愿：平安 发财。@滴滴出行司机中心官方账号 | H21: 299 | I21: ='详细数据'!AC35+'详细数据'!AC55 | J21: 7295 | K21: ='详细数据'!J35+'详细数据'!J55 | L21: =K21/J21 | M21: 无匹配类别 | N21: 无匹配类别 | P21: 7295 | Q21: =IF(J21="","",IF(J21>=500000,"S 级",IF(J21>=100000,"A 级",IF(J21>=50000,"B 级","C 级"))))
B22: =A22+7 | C22: 无法投放 | D22: ✎﹏ ℳ伱♡吥懂💞ꦿ᭄ | E22: https://www.douyin.com/video/7613759148690695077 | F22: / | G22: 这么多年坐滴滴打车，是我遇上最好的一个滴滴司机，肯定会给你好评呀。 | H22: 147 | I22: / | J22: / | K22: / | L22: / | M22: / | P22: /
A23: 46089 | B23: =A23+7 | C23: 投放完毕 | D23: 一点也不酷啊。 | E23: https://www.douyin.com/video/7614841048691419327 | F23: 2026/3/9投放500元2026/3/12投放500元2026/3/13投放500元 | G23: 打了2个小时滴滴，取消了半天，终于打到了。氛围灯也开了，最好的安排也安排了，总裁座椅也给他调了。他常出现的地方我给你们标记出来了 | H23: 316 | I23: ='详细数据'!AC34+'详细数据'!AC54+'详细数据'!AC63 | J23: 33030 | K23: ='详细数据'!J34+'详细数据'!J54+'详细数据'!J63 | L23: =K23/J23 | M23: 产品力 | N23: 专车/豪华车 | P23: 33030 | Q23: =IF(J23="","",IF(J23>=500000,"S 级",IF(J23>=100000,"A 级",IF(J23>=50000,"B 级","C 级"))))
B24: =A24+7 | C24: 无法投放 | D24: 杨哥来了 | E24: https://www.douyin.com/note/7614679701290263147 | F24: / | G24: 雨夜武汉，一位滴滴司机，让我读懂什。雨夜守护 致敬武汉暖心司机 | H24: 3657 | I24: / | J24: / | K24: / | L24: / | M24: / | P24: /
A25: 46089 | B25: =A25+7 | C25: 投放完毕 | D25: 莫陌墨默 | E25: https://www.douyin.com/video/7614604940937363313 | F25: 2026/3/9投放500元2026/3/12投放500元2026/3/13投放499.7元 | G25: 回家路上，司机自娱自乐，一句“不会让我亲脆”让我破防，简直是氛围组，然后人生第一次跟滴滴合唱😂😂😂，憋怕我伤心 | H25: 370 | I25: ='详细数据'!AC33+'详细数据'!AC53+'详细数据'!AC62 | J25: 5009 | K25: ='详细数据'!J33+'详细数据'!J53+'详细数据'!J62 | L25: =K25/J25 | M25: 司机 | N25: 司乘互动 | P25: 5009 | Q25: =IF(J25="","",IF(J25>=500000,"S 级",IF(J25>=100000,"A 级",IF(J25>=50000,"B 级","C 级"))))
A26: 46088 | B26: =A26+7 | C26: 投放完毕 | D26: ⁺✞ʚ佐鸣重度依赖ɞ✟₊ | E26: https://www.douyin.com/note/7614491818344720739 | F26: 2026/3/9投放500元2026/3/12投放500元 | G26: 上天入地我再也找不到佐鸣这样美好的家产了。家产要永远幸福！ #佐鸣 #佐鸣永远热恋 #滴滴打车 3799！ | H26: 616 | I26: ='详细数据'!AC32+'详细数据'!AC52 | J26: 3105 | K26: ='详细数据'!J32+'详细数据'!J52 | L26: =K26/J26 | M26: 无匹配类别 | N26: 无匹配类别 | P26: 3105 | Q26: =IF(J26="","",IF(J26>=500000,"S 级",IF(J26>=100000,"A 级",IF(J26>=50000,"B 级","C 级"))))
A27: 46090 | B27: =A27+7 | C27: 投放完毕 | D27: 云子 | E27: https://www.douyin.com/video/7615259770899058779 | F27: 2026/3/10投放500元 | G27: 谢谢我的好闺蜜陪我一起闹，还好俺两个一瓶10年都没多，可以安全到家，我好幸运的就是，滴滴师傅是个女同胞，谢谢感恩遇见 | H27: 104 | I27: ='详细数据'!AC42 | J27: 708 | K27: ='详细数据'!J42 | L27: =K27/J27 | M27: 司机 | N27: 女司机 | P27: 708 | Q27: =IF(J27="","",IF(J27>=500000,"S 级",IF(J27>=100000,"A 级",IF(J27>=50000,"B 级","C 级"))))
A28: 46090 | B28: =A28+7 | C28: 投放完毕 | D28: 温暖小孩 | E28: https://www.douyin.com/note/7615023865811614964 | F28: 2026/3/10投放500元 | G28: 滴滴打到帕萨特！第一次体验直接被后排圈粉✨ | H28: 105 | I28: ='详细数据'!AC41 | J28: 924 | K28: ='详细数据'!J41 | L28: =K28/J28 | M28: 车内 | N28: 特殊车型/车衣 | P28: 924 | Q28: =IF(J28="","",IF(J28>=500000,"S 级",IF(J28>=100000,"A 级",IF(J28>=50000,"B 级","C 级"))))
A29: 46089 | B29: =A29+7 | C29: 投放完毕 | D29: 🌈✨小趙媳妇儿✨💕 | E29: https://www.douyin.com/note/7615049142386066043 | F29: 2026/3/10投放500元 | G29: 你们有没有打到过那种车内气味很重的车 打到你们会怎么做 #滴滴司机 #干净的车内环境 | H29: 82 | I29: ='详细数据'!AC40 | J29: 1027 | K29: ='详细数据'!J40 | L29: =K29/J29 | M29: 车内环境投诉 | N29: 烟味/异味 | P29: 1027 | Q29: =IF(J29="","",IF(J29>=500000,"S 级",IF(J29>=100000,"A 级",IF(J29>=50000,"B 级","C 级"))))
A30: 46089 | B30: =A30+7 | C30: 投放完毕 | D30: 小水滴💧 | E30: https://www.douyin.com/note/7614899619931912369 | F30: 2026/3/10投放500元 | G30: 这个妇女节做了一件小事：给所有载过我的女司机发祝福红包🧧 | H30: 448 | I30: ='详细数据'!AC39 | J30: 961 | K30: ='详细数据'!J39 | L30: =K30/J30 | M30: 司机 | N30: 女司机 | P30: 961 | Q30: =IF(J30="","",IF(J30>=500000,"S 级",IF(J30>=100000,"A 级",IF(J30>=50000,"B 级","C 级"))))
A31: 46090 | B31: =A31+7 | C31: 投放完毕 | D31: 玖张机 | E31: https://www.douyin.com/video/7615266309736562682 | F31: 2026/3/11投放500元 | G31: 滴滴打车好评，可以优先选择女性司机。#滴滴 #打车软件 #安全出行 #女性 #解锁新功能 | H31: 141 | I31: ='详细数据'!AC45 | J31: 514 | K31: ='详细数据'!J45 | L31: =K31/J31 | M31: 产品力 | N31: 女性友好计划 | P31: 514 | Q31: =IF(J31="","",IF(J31>=500000,"S 级",IF(J31>=100000,"A 级",IF(J31>=50000,"B 级","C 级"))))
A32: 46092 | B32: =A32+7 | C32: 投放完毕 | D32: 小辉哥 | E32: https://www.douyin.com/video/7615783338746236337 | F32: 2026/3/11投放500元2026/3/12投放500元2026/3/13投放500元2026/3/16投放500元2026/3/17投放500元 | G32: #滴滴，#出租车，朋友们，在陌生的城市，打滴滴还是方便一点！ | H32: 138 | I32: ='详细数据'!AC44+'详细数据'!AC51+'详细数据'!AC61+'详细数据'!AC68+'详细数据'!AC72 | J32: 9518 | K32: ='详细数据'!J44+'详细数据'!J51+'详细数据'!J61+'详细数据'!J68+'详细数据'!J72 | L32: =K32/J32 | M32: 场景 | N32: 旅游出行 | P32: 9518 | Q32: =IF(J32="","",IF(J32>=500000,"S 级",IF(J32>=100000,"A 级",IF(J32>=50000,"B 级","C 级"))))
A33: 46092 | B33: =A33+7 | C33: 投放完毕 | D33: 绛珠仙子成长日记 | E33: https://www.douyin.com/video/7615713873504923322 | F33: 2026/3/11投放500元2026/3/12投放500元2026/3/13投放500元2026/3/16投放500元2026/3/17投放1000元2026/3/18投放9999.79元 | G33: 5.0分的滴滴司机 师傅我听懂了 其实你在告诉我 这个世界上没有定义 只有视角不同 但我此刻有个善良的定义 那就是你的那一句 “为什么你大半夜去人民医院” 以及你的善意的开导 但我是个杠精 我天天带着答案问问题 请原谅我 谢谢你，陌生人 至少此刻你的善良给我带来了开心 我对很多东西都没有欲望 但是对善意的瞬间 充满欲望 渴求遇见它享受它 #司机师傅 #欲望 #善良 | H33: 103 | I33: ='详细数据'!AC43+'详细数据'!AC50+'详细数据'!AC60+'详细数据'!AC67+'详细数据'!AC69+'详细数据'!AC75 | J33: 50277 | K33: ='详细数据'!J43+'详细数据'!J50+'详细数据'!J60+'详细数据'!J67+'详细数据'!J69+'详细数据'!J75 | L33: =K33/J33 | M33: 司机 | N33: 司乘温暖 | P33: 50277 | Q33: =IF(J33="","",IF(J33>=500000,"S 级",IF(J33>=100000,"A 级",IF(J33>=50000,"B 级","C 级"))))
A34: 46092 | B34: =A34+7 | C34: 投放完毕 | D34: 好人好梦👑 | E34: https://www.douyin.com/note/7615950184098960602 | F34: 2026/3/12投放500元 | G34: 今天特别感谢滴滴车主这位大姐拾金不昧的精神，拾到我的皮夹克外套和钱包。特地把平台的接单取消，送到我厂里。关键是身份证，银行卡，医保卡补办太费事了。现在还是好人多。失而复得我很开心。祝好人一生平安！ | H34: 82 | I34: ='详细数据'!AC49 | J34: 1155 | K34: ='详细数据'!J49 | L34: =K34/J34 | M34: 司机 | N34: 失物返还 | P34: 1155 | Q34: =IF(J34="","",IF(J34>=500000,"S 级",IF(J34>=100000,"A 级",IF(J34>=50000,"B 级","C 级"))))
A35: 46092 | B35: =A35+7 | C35: 投放完毕 | D35: 火光 | E35: https://www.douyin.com/note/7615669310942601338 | F35: 2026/3/12投放500元 | G35: 不敢直视师傅的眼睛。#滴滴 #我爱你 | H35: 75 | I35: ='详细数据'!AC48 | J35: 759 | K35: ='详细数据'!J48 | L35: =K35/J35 | M35: 司机 | N35: 司乘互动 | P35: 759 | Q35: =IF(J35="","",IF(J35>=500000,"S 级",IF(J35>=100000,"A 级",IF(J35>=50000,"B 级","C 级"))))
A36: 46092 | B36: =A36+7 | C36: 投放完毕 | D36: 财神爷的小心肝🐉 | E36: https://www.douyin.com/note/7616010066626177211 | F36: 2026/3/12投放499.82元 | G36: 今天因为闹钟没响起晚了所以打滴滴赶去上班，像往常打车一样，我上车报了尾号便开始刷手机，正常都是一路无言。 | H36: 107 | I36: ='详细数据'!AC47 | J36: 1083 | K36: ='详细数据'!J47 | L36: =K36/J36 | M36: 场景 | N36: 通勤上下班 | P36: 1083 | Q36: =IF(J36="","",IF(J36>=500000,"S 级",IF(J36>=100000,"A 级",IF(J36>=50000,"B 级","C 级"))))
A37: 46092 | B37: =A37+7 | C37: 投放完毕 | D37: 秋日胡杨 | E37: https://www.douyin.com/note/7615977113706843382 | F37: 2026/3/12投放499.89元 | G37: 揭阳很好，下次还来 揭阳是唯一个被本地人喊"欢迎"的城市，也是唯一个不被叫"外省仔"的城市 | H37: 90 | I37: ='详细数据'!AC45 | J37: 337 | K37: ='详细数据'!J46 | L37: =K37/J37 | M37: 场景 | N37: 旅游出行 | P37: 337 | Q37: =IF(J37="","",IF(J37>=500000,"S 级",IF(J37>=100000,"A 级",IF(J37>=50000,"B 级","C 级"))))
A38: 46093 | B38: =A38+7 | C38: 投放完毕 | D38: 故宫楚楚日常 | E38: https://www.douyin.com/video/7616359394191938022 | F38: 2026/3/13投放500元 | G38: 整个北京唱歌最好听的滴滴司机被我碰到啦！#故宫楚楚 #滴滴司机 #滴滴司机唱歌 #北京生活 #北京滴滴司机 | H38: 159 | I38: ='详细数据'!AC59 | J38: 1432 | K38: ='详细数据'!J59 | L38: =K38/J38 | M38: 司机 | N38: 司乘互动 | P38: 1432 | Q38: =IF(J38="","",IF(J38>=500000,"S 级",IF(J38>=100000,"A 级",IF(J38>=50000,"B 级","C 级"))))
A39: 46093 | B39: =A39+7 | C39: 投放完毕 | D39: 看他慢慢爱 | E39: https://www.douyin.com/note/7616183547221202259 | F39: 2026/3/13投放500元 | G39: 滴滴可以设置女司机偏好啦。总算是可以小范围避免那些不稳定因素了#滴滴女司机设置 | H39: 119 | I39: ='详细数据'!AC58 | J39: 853 | K39: ='详细数据'!J58 | L39: =K39/J39 | M39: 产品力 | N39: 女性友好计划 | P39: 853 | Q39: =IF(J39="","",IF(J39>=500000,"S 级",IF(J39>=100000,"A 级",IF(J39>=50000,"B 级","C 级"))))
A40: 46093 | B40: =A40+7 | C40: 投放完毕 | D40: 幸运天使（小齐姑姑） | E40: https://www.douyin.com/note/7616286705788479977 | F40: 2026/3/13投放500元 | G40: 正月二十四，晴天，今日解锁滴滴出行，没想到这么方便，电话发出去三两分钟车马上就到，想去那去哪，遇到健谈的师傅一路上还不感觉孤单，轻松又自在，再也不用因为你不拉我出门让我等的憋气人了，哈哈。 | H40: 114 | I40: ='详细数据'!AC57 | J40: 496 | K40: ='详细数据'!J57 | L40: =K40/J40 | M40: 产品力 | N40: 叫车快 | P40: 496 | Q40: =IF(J40="","",IF(J40>=500000,"S 级",IF(J40>=100000,"A 级",IF(J40>=50000,"B 级","C 级"))))
...

Sheet 4月加热汇总
A1: 发布日期 | B1: 投放截止日期 | C1: 状态 | D1: 达人名称 | E1: 链接 | F1: 投放记录 xx日投放xx元 | G1: 标题 | H1: 投前互动量 | I1: 投放互动量 | J1: 投放后点赞量 | K1: 投放后收藏量 | L1: 投放后评论量 | M1: 投放后转发量 | N1: 总互动量 | O1: 总投放金额 | P1: 综合cpe *投入/笔记外层互动数据 | Q1: 一级分类 | R1: 二级分类 | S1: 备注 | T1: 爆款定级
A2: 汇总 | H2: - | I2: - | N2: =SUM(N3:N98) | O2: =SUM(O3:O98) | P2: =O2/N2
A3: 46113 | B3: =A3+7 | C3: 投放完毕 | D3: 养一只蒙丢丢 | E3: https://www.douyin.com/video/7623768838857578048 | F3: 2026/4/2投放1000元 | G3: 北京的滴滴司机也太好了吧🤗，滴滴快车享受专车都享受不了的待遇，快下车了看我们都没拿，然后他抓了四个🍊送到了我们手里边#抖加小助手 #抖音热门 #抖音热门小助手 | H3: 99 | I3: ='详细数据'!AC132 | J3: 3830 | K3: 35 | L3: 49 | M3: 174 | N3: =SUM(J3:M3) | O3: ='详细数据'!J132 | P3: =O3/N3 | Q3: 司机 | R3: 司乘温暖 | T3: =IF(N3="","",IF(N3>=500000,"S 级",IF(N3>=100000,"A 级",IF(N3>=50000,"B 级","C 级"))))
A4: 46114 | B4: =A4+7 | C4: 投放完毕 | D4: 晓雅姐 | E4: https://www.douyin.com/note/7624113880570299215 | F4: 2026/4/3投放1000元 | G4: #出行 #专车接送 乘坐这样的专车出行，怎么会有司乘矛盾呢。 | H4: 81 | I4: ='详细数据'!AC134 | J4: 1407 | K4: 39 | L4: 56 | M4: 3 | N4: =SUM(J4:M4) | O4: ='详细数据'!J133 | P4: =O4/N4 | Q4: 产品力 | R4: 专车/豪华车 | T4: =IF(N4="","",IF(N4>=500000,"S 级",IF(N4>=100000,"A 级",IF(N4>=50000,"B 级","C 级"))))
A5: 46116 | B5: =A5+7 | C5: 投放完毕 | D5: Maisy | E5: https://www.douyin.com/video/7624862115832787121 | F5: 2026/4/7投放1000元2026/4/8投放5000元 | G5: 大雨着急去和朋友吃饭被困在公司于是滴滴师傅把车停在最近的停车场带伞来接我 路上跟我描述车况并一直道歉 从前这样的事情只有父亲做过 相同的还有那把倾斜的伞和淋湿的衣服#雨 #沈阳美食 #滴滴司机 #服务业 | H5: 474 | I5: ='详细数据'!AC139 | J5: 24000 | K5: 347 | L5: 1815 | M5: 410 | N5: =SUM(J5:M5) | O5: ='详细数据'!J134+'详细数据'!J141 | P5: =O5/N5 | Q5: 司机 | R5: 司乘温暖 | T5: =IF(N5="","",IF(N5>=500000,"S 级",IF(N5>=100000,"A 级",IF(N5>=50000,"B 级","C 级"))))
A6: 46115 | B6: =A6+7 | C6: 投放完毕 | D6: 真褒义词！ | E6: https://www.douyin.com/video/7624320840444438116 | F6: 2026/4/7投放1000元 | G6: 重庆新华网你好事做尽！！！！也是在滴滴上自己点歌了#重庆 #张云雷 #滴滴出行 | H6: 90 | I6: ='详细数据'!AC138 | J6: 1666 | K6: 52 | L6: 35 | M6: 10 | N6: =SUM(J6:M6) | O6: ='详细数据'!J135 | P6: =O6/N6 | Q6: 车内 | R6: 司机自发装置 | T6: =IF(N6="","",IF(N6>=500000,"S 级",IF(N6>=100000,"A 级",IF(N6>=50000,"B 级","C 级"))))
A7: 46117 | B7: =A7+7 | C7: 投放完毕 | D7: 茉 | E7: https://www.douyin.com/note/7625245014687938233 | F7: 2026/4/7投放1000元 | G7: 女性主义。今天经历了很多幸福的事情。第一件事：今天第一次启用了刷到的“滴滴女性友好计划”，即优先推荐女司机。 | H7: 189 | I7: ='详细数据'!AC137 | J7: 1963 | K7: 37 | L7: 15 | M7: 21 | N7: =SUM(J7:M7) | O7: ='详细数据'!J136 | P7: =O7/N7 | Q7: 产品力 | R7: 女性友好计划 | T7: =IF(N7="","",IF(N7>=500000,"S 级",IF(N7>=100000,"A 级",IF(N7>=50000,"B 级","C 级"))))
A8: 46117 | B8: =A8+7 | C8: 投放完毕 | D8: ￴￴ ￴￴陈伟 | E8: https://www.douyin.com/note/7624963816623740027 | F8: 2026/4/7投放1000元2026/4/8投放10000元2026/4/9投放5000元2026/4/10投放5000元 | G8: 那天我打了个滴滴 和往常一样开了车门要准备上车 可那天我一打开车门映入眼帘看到司机车上贴满了各国的钞票 和各国的祝福语 | H8: 88 | I8: ='详细数据'!AC136+'详细数据'!AC145+'详细数据'!AC149 | J8: 287000 | K8: 5917 | L8: 637 | M8: 24000 | N8: =SUM(J8:M8) | O8: ='详细数据'!J137+'详细数据'!J140+'详细数据'!J145+'详细数据'!J149 | P8: =O8/N8 | Q8: 车内 | R8: 司机自发装置 | T8: =IF(N8="","",IF(N8>=500000,"S 级",IF(N8>=100000,"A 级",IF(N8>=50000,"B 级","C 级"))))
A9: 46117 | B9: =A9+7 | C9: 投放完毕 | D9: 牙抖音不抖🪥 | E9: https://www.douyin.com/video/7625090564824947065 | F9: 2026/4/7投放1000元 | G9: 长见识了，才知道还有滴滴公交车3块钱一个人#滴滴公交车 # | H9: 35 | I9: ='详细数据'!AC135 | J9: 2298 | K9: 51 | L9: 84 | M9: 107 | N9: =SUM(J9:M9) | O9: ='详细数据'!J138 | P9: =O9/N9 | Q9: 产品力 | R9: 网约公交 | T9: =IF(N9="","",IF(N9>=500000,"S 级",IF(N9>=100000,"A 级",IF(N9>=50000,"B 级","C 级"))))
A10: 46119 | B10: =A10+7 | C10: 投放完毕 | D10: 纯爷们 | E10: https://www.douyin.com/note/7625760714330410816 | F10: 2026/4/8投放835.21元 | G10: 昨天肚子疼了一天，从早上九点多到夜里十一点多，实在忍不住了，去了医院，结果说是急性阑尾炎。 | H10: 81 | I10: ='详细数据'!AC143 | J10: 图文下线 | N10: =SUM(J10:M10) | O10: ='详细数据'!J143 | P10: =O10/N10 | Q10: 场景 | R10: 医院/就医 | T10: =IF(N10="","",IF(N10>=500000,"S 级",IF(N10>=100000,"A 级",IF(N10>=50000,"B 级","C 级"))))
A11: 46119 | B11: =A11+7 | C11: 在投 | D11: 哎呦～wei♞🌽 | E11: https://www.douyin.com/note/7625846621917471208 | F11: 2026/4/8投放1000元 | G11: 兖州真的是一个很有爱的城市，滴滴师傅都好有礼貌，也很有爱心 | H11: 87 | I11: ='详细数据'!AC142 | J11: 542 | K11: 34 | L11: 12 | M11: 3 | N11: =SUM(J11:M11) | O11: ='详细数据'!J142 | P11: =O11/N11 | Q11: 司机 | R11: 司机服务 | T11: =IF(N11="","",IF(N11>=500000,"S 级",IF(N11>=100000,"A 级",IF(N11>=50000,"B 级","C 级"))))
A12: 46120 | B12: =A12+7 | C12: 投放完毕 | D12: 晓雅姐 | E12: https://www.douyin.com/note/7626240521292568483 | F12: 2026/4/9投放1000元 | G12: #出行 #专车接送 稳稳的好评给这司机，上车没有多久就很困睡着了 | H12: 132 | I12: ='详细数据'!AC144 | J12: 2000 | K12: 37 | L12: 87 | M12: 12 | N12: =SUM(J12:M12) | O12: ='详细数据'!J144 | P12: =O12/N12 | Q12: 产品力 | R12: 专车/豪华车 | T12: =IF(N12="","",IF(N12>=500000,"S 级",IF(N12>=100000,"A 级",IF(N12>=50000,"B 级","C 级"))))
A13: 46120 | B13: =A13+7 | C13: 投放完毕 | D13: 朵朵妹妹 | E13: https://www.douyin.com/video/7626383694223907429 | F13: 2026/4/10投放1000元 | G13: 这次体验感真的超好，坐到了极氪009，晕车的我突然不晕了，司机亲自开门，车上再也没有异味，都是香香的，有吃有喝 | H13: 96 | I13: ='详细数据'!AC148 | J13: 2089 | K13: 54 | L13: 177 | M13: 75 | N13: =SUM(J13:M13) | O13: ='详细数据'!J148 | P13: =O13/N13 | Q13: 车内 | R13: 特殊车型/车衣 | T13: =IF(N13="","",IF(N13>=500000,"S 级",IF(N13>=100000,"A 级",IF(N13>=50000,"B 级","C 级"))))
A14: 46121 | B14: =A14+7 | C14: 投放完毕 | D14: 善缘 | E14: https://www.douyin.com/note/7626557894406165434 | F14: 2026/4/10投放1000元 | G14: 这两天被太多温柔善意包裹着 | H14: 101 | I14: ='详细数据'!AC147 | J14: 1848 | K14: 66 | L14: 121 | M14: 3 | N14: =SUM(J14:M14) | O14: ='详细数据'!J147 | P14: =O14/N14 | Q14: 司机 | R14: 司乘温暖 | T14: =IF(N14="","",IF(N14>=500000,"S 级",IF(N14>=100000,"A 级",IF(N14>=50000,"B 级","C 级"))))
A15: 46121 | B15: =A15+7 | C15: 投放完毕 | D15: 薇薇安的闪电侠 | E15: https://www.douyin.com/video/7626715483103183604 | F15: 2026/4/10投放1000元 | G15: 第一次打到播放音乐的滴滴打车，还是我喜欢的音乐，并且还不臭的车，必须给司机大哥发个红包表示感谢一下，希望司机不要嫌弃太少哈 #滴滴打车 | H15: 83 | I15: ='详细数据'!AC146 | J15: 3338 | K15: 82 | L15: 244 | M15: 28 | N15: =SUM(J15:M15) | O15: ='详细数据'!J146 | P15: =O15/N15 | Q15: 车内 | R15: 司机自发装置 | T15: =IF(N15="","",IF(N15>=500000,"S 级",IF(N15>=100000,"A 级",IF(N15>=50000,"B 级","C 级"))))
A16: 46123 | B16: =A16+7 | C16: 投放完毕 | D16: Y悟空 | E16: https://www.douyin.com/video/7627467421783603045 | F16: 2026/4/13投放1000元2026/4/14投放5000元2026/4/15投放10000元 | G16: #潮玩驾驶 #车载搭子 #滴滴司机 | H16: 367 | I16: ='详细数据'!AC153+'详细数据'!AC154+'详细数据'!AC158 | J16: 131000 | K16: 2525 | L16: 1003 | M16: 32000 | N16: =SUM(J16:M16) | O16: ='详细数据'!J153+'详细数据'!J154+'详细数据'!J158 | P16: =O16/N16 | Q16: 车内 | R16: 司机自发装置 | T16: =IF(N16="","",IF(N16>=500000,"S 级",IF(N16>=100000,"A 级",IF(N16>=50000,"B 级","C 级"))))
A17: 46122 | B17: =A17+7 | C17: 投放完毕 | D17: 人间小迷糊 | E17: https://www.douyin.com/note/7626984999901013113 | F17: 2026/4/13投放1000元 | G17: 今天的滴滴司机应该是一个灵魂很有趣的人呢👍多么可可爱爱ෆ╹ .̮ ╹ෆ的人，才能配出这么有趣的文字~ | H17: 74 | I17: ='详细数据'!AC152 | J17: 272 | K17: 21 | L17: 14 | M17: 16 | N17: =SUM(J17:M17) | O17: ='详细数据'!J152 | P17: =O17/N17 | Q17: 车内 | R17: 留言本 | T17: =IF(N17="","",IF(N17>=500000,"S 级",IF(N17>=100000,"A 级",IF(N17>=50000,"B 级","C 级"))))
A18: 46123 | B18: =A18+7 | C18: 无法投放 | D18: 黄山竹 | E18: https://www.douyin.com/note/7627440028503106771 | G18: 方便市民出行 | H18: 64
A19: 46124 | B19: =A19+7 | C19: 投放完毕 | D19: beo_mmunga_ | E19: https://www.douyin.com/video/7627890045047581027 | F19: 2026/4/13投放598.97元 | G19: 遇到了这辈子最合拍的滴滴师傅😂😂#滴滴司机 #心软的神 #k歌之王 | H19: 79 | I19: ='详细数据'!AC150 | J19: 视频下线 | N19: =SUM(J19:M19) | O19: ='详细数据'!J150 | P19: =O19/N19 | Q19: 司机 | R19: 司乘互动 | T19: =IF(N19="","",IF(N19>=500000,"S 级",IF(N19>=100000,"A 级",IF(N19>=50000,"B 级","C 级"))))
A20: 46125 | B20: =A20+7 | C20: 投放完毕 | D20: CHN | E20: https://www.douyin.com/video/7628055768176180586 | F20: 2026/4/14投放1000元 | G20: 滴滴真的什么车都能打到！曾经的豪华电车，有幸优享到了，车还是很不错的，尤其劳斯莱斯的开门！ #高合hiphix #滴滴 #新能源汽车 | H20: 128 | I20: ='详细数据'!AC156 | J20: 2013 | K20: 64 | L20: 72 | M20: 60 | N20: =SUM(J20:M20) | O20: ='详细数据'!J156 | P20: =O20/N20 | Q20: 车内 | R20: 特殊车型/车衣 | T20: =IF(N20="","",IF(N20>=500000,"S 级",IF(N20>=100000,"A 级",IF(N20>=50000,"B 级","C 级"))))
A21: 46124 | B21: =A21+7 | C21: 投放完毕 | D21: ☎️@永欢生态农场 | E21: https://www.douyin.com/video/7627656361078613477 | F21: 2026/4/14投放1000元 | G21: 打个滴滴司机师傅都是个美女，现在行业那么卷了吗？ | H21: 82 | I21: ='详细数据'!AC155 | J21: 2941 | K21: 57 | L21: 111 | M21: 24 | N21: =SUM(J21:M21) | O21: ='详细数据'!J155 | P21: =O21/N21 | Q21: 司机 | R21: 女司机 | T21: =IF(N21="","",IF(N21>=500000,"S 级",IF(N21>=100000,"A 级",IF(N21>=50000,"B 级","C 级"))))
A22: 46126 | B22: =A22+7 | C22: 投放完毕 | D22: 茉香·姜婷婷 | E22: https://www.douyin.com/video/7628568501427008241 | F22: 2026/4/15投放1000元 | G22: 我们不是他人口中的“小店小厂”，当我们集结成为匠心联盟，蚂蚁军团可食象。 | H22: 184 | I22: ='详细数据'!AC159 | J22: 1108 | K22: 71 | L22: 49 | M22: 21 | N22: =SUM(J22:M22) | O22: ='详细数据'!J159 | P22: =O22/N22 | Q22: 无匹配类别 | R22: 无匹配类别 | T22: =IF(N22="","",IF(N22>=500000,"S 级",IF(N22>=100000,"A 级",IF(N22>=50000,"B 级","C 级"))))
A23: 46126 | B23: =A23+7 | C23: 投放完毕 | D23: 保山小韩 | E23: https://www.douyin.com/video/7628593020561465713 | F23: 2026/4/15投放1000元 | G23: 这是我坐过最暖心的滴滴车，人都会疲惫，会黯淡，但也会因为某个瞬间重新爱上生活#滴滴车内的小细节#云南保山#治愈世界治愈你 | H23: 242 | I23: ='详细数据'!AC157 | J23: 3088 | K23: 43 | L23: 84 | M23: 525 | N23: =SUM(J23:M23) | O23: ='详细数据'!J157 | P23: =O23/N23 | Q23: 车内 | R23: 司机自发装置 | T23: =IF(N23="","",IF(N23>=500000,"S 级",IF(N23>=100000,"A 级",IF(N23>=50000,"B 级","C 级"))))
A24: 46125 | B24: =A24+7 | C24: 投放完毕 | D24: 恭喜啊小富婆 | E24: https://www.douyin.com/video/7628175992222109553 | F24: 2026/4/16投放1000元 | G24: 隔一天洗一次！干一行爱一行，一行白鹭上青天！ #滴滴司机 #日常vlog #搞笑 #搞笑视频 #出门必备 | H24: 72 | I24: ='详细数据'!AC161 | J24: 1737 | K24: 27 | L24: 50 | M24: 6 | N24: =SUM(J24:M24) | O24: ='详细数据'!J161 | P24: =O24/N24 | Q24: 无匹配类别 | R24: 无匹配类别 | T24: =IF(N24="","",IF(N24>=500000,"S 级",IF(N24>=100000,"A 级",IF(N24>=50000,"B 级","C 级"))))
A25: 46128 | B25: =A25+7 | C25: 投放完毕 | D25: 汪涛和导盲犬叮当 | E25: https://www.douyin.com/video/7629141999672840169 | F25: 2026/4/16投放1000元2026/4/17投放5000元 | G25: 带导盲犬叮当在福州坐滴滴，被一位暖心交警狠狠治愈。 带着导盲犬叮当在福州路边等候滴滴，因视线不便，我只能将手机贴在耳边听单，加上排队车辆较多，在路口徘徊等待了很久。 | H25: 347 | I25: ='详细数据'!AC160+'详细数据'!AC163 | J25: 19000 | K25: 297 | L25: 115 | M25: 91 | N25: =SUM(J25:M25) | O25: ='详细数据'!J160+'详细数据'!J163 | P25: =O25/N25 | Q25: 司机 | R25: 司乘温暖 | T25: =IF(N25="","",IF(N25>=500000,"S 级",IF(N25>=100000,"A 级",IF(N25>=50000,"B 级","C 级"))))
A26: 46127 | B26: =A26+7 | C26: 投放完毕 | D26: 兵哥跑车 | E26: https://www.douyin.com/video/7628928486560089529 | F26: 2026/4/17投放1000元 | G26: 滴滴香卡来啦#滴滴北京限定香卡 #把北京景点挂到车上 | H26: 929 | I26: ='详细数据'!AC162 | J26: 1439 | K26: 59 | L26: 33 | M26: 3 | N26: =SUM(J26:M26) | O26: ='详细数据'!J162 | P26: =O26/N26 | Q26: 车内 | R26: 香卡 | T26: =IF(N26="","",IF(N26>=500000,"S 级",IF(N26>=100000,"A 级",IF(N26>=50000,"B 级","C 级"))))
A27: 46131 | B27: =A27+7 | C27: 投放完毕 | D27: 桃子欧尼 | E27: https://www.douyin.com/note/7630389147651540148 | F27: 2026/4/20投放1000元 | G27: 加班的坏心情得到了治愈～#打车奇遇 #退役军人 #滴滴司机 #致敬 #dou上热门 | H27: 112 | I27: ='详细数据'!AC171 | J27: 2872 | K27: 15 | L27: 29 | M27: 57 | N27: =SUM(J27:M27) | O27: ='详细数据'!J171 | P27: =O27/N27 | Q27: 司机 | R27: 特殊身份-退伍军人 | T27: =IF(N27="","",IF(N27>=500000,"S 级",IF(N27>=100000,"A 级",IF(N27>=50000,"B 级","C 级"))))
A28: 46131 | B28: =A28+7 | C28: 投放完毕 | D28: 🧀 | E28: https://www.douyin.com/note/7630280919329366708 | F28: 2026/4/20投放1000元 | G28: 第一次打到聋哑人司机的车，上车习惯性报了手机尾号，没注意到提示牌 习惯性跟司机打招呼 没理我 当我抬头的时候司机拿着提示牌给我看 这才明白他是 | H28: 448 | I28: ='详细数据'!AC170 | J28: 1421 | K28: 14 | L28: 19 | M28: 8 | N28: =SUM(J28:M28) | O28: ='详细数据'!J170 | P28: =O28/N28 | Q28: 司机 | R28: 特殊身份-听障司机 | T28: =IF(N28="","",IF(N28>=500000,"S 级",IF(N28>=100000,"A 级",IF(N28>=50000,"B 级","C 级"))))
A29: 46131 | B29: =A29+7 | C29: 投放完毕 | D29: 佩琪 | E29: https://www.douyin.com/video/7630163601161398178 | F29: 2026/4/20投放1000元 | G29: #滴滴司机 今天遇到一个57岁还在开滴滴的叔叔，他说他要挣钱，他儿子开了一个装修公司在亏钱，他希望可以帮他一把，看见他跟我父亲的年龄差不多大，莫名有一股亲切 | H29: 259 | I29: ='详细数据'!AC166 | J29: 1086 | K29: 28 | L29: 68 | M29: 11 | N29: =SUM(J29:M29) | O29: ='详细数据'!J166 | P29: =O29/N29 | Q29: 司机 | R29: 司乘互动 | T29: =IF(N29="","",IF(N29>=500000,"S 级",IF(N29>=100000,"A 级",IF(N29>=50000,"B 级","C 级"))))
A30: 46130 | B30: =A30+7 | C30: 在投 | D30: 知青 | E30: https://www.douyin.com/video/7629911775865505906 | F30: 2026/4/20投放1000元 | G30: 上午去南昌汉代海昏候博物馆参观，我乘坐滴滴网约车，有幸遇上一个即开车技术好，又是南昌通的师傅，让我一路开心。#南昌交通 #司机 #夫妻日常 #海昏侯博物馆 | H30: 92 | I30: ='详细数据'!AC169 | J30: 857 | K30: 63 | L30: 42 | M30: 2 | N30: =SUM(J30:M30) | O30: ='详细数据'!J169 | P30: =O30/N30 | Q30: 场景 | R30: 旅游出行 | T30: =IF(N30="","",IF(N30>=500000,"S 级",IF(N30>=100000,"A 级",IF(N30>=50000,"B 级","C 级"))))
A31: 46130 | B31: =A31+7 | C31: 投放完毕 | D31: 汪涛和导盲犬叮当 | E31: https://www.douyin.com/video/7630071089049654198 | F31: 2026/4/20投放1000元 | G31: 带叮当在福州坐滴滴遇到一位热心司机，一路交谈满是温暖！ 带着导盲犬叮当出行，在福州偶遇一位暖心滴滴司机。一路交谈满是善意，司机细心询问导盲犬的相关事宜 | H31: 202 | I31: ='详细数据'!AC168 | J31: 464 | K31: 32 | L31: 28 | M31: 7 | N31: =SUM(J31:M31) | O31: ='详细数据'!J168 | P31: =O31/N31 | Q31: 司机 | R31: 司机服务 | T31: =IF(N31="","",IF(N31>=500000,"S 级",IF(N31>=100000,"A 级",IF(N31>=50000,"B 级","C 级"))))
A32: 46131 | B32: =A32+7 | C32: 投放完毕 | D32: 英 | E32: https://www.douyin.com/video/7630474109919557051 | F32: 2026/4/20投放1000元 | G32: 2026.4.19日，今天从峨眉坐滴滴巴士来成都，就是为了明天带妈妈到华西看病。提前一天过来，就是为了省钱、省时间、少折腾。 | H32: 7 | I32: ='详细数据'!AC167 | J32: 230 | K32: 27 | L32: 12 | M32: 2 | N32: =SUM(J32:M32) | O32: ='详细数据'!J167 | P32: =O32/N32 | Q32: 场景 | R32: 医院/就医 | T32: =IF(N32="","",IF(N32>=500000,"S 级",IF(N32>=100000,"A 级",IF(N32>=50000,"B 级","C 级"))))
A33: 46131 | B33: =A33+7 | C33: 投放完毕 | D33: 飘雪 | E33: https://www.douyin.com/video/7630433467185514597 | F33: 2026/4/20投放1000元 | G33: #滴滴站点巴士 #成都到广元39.9 | H33: 46 | I33: ='详细数据'!AC165 | J33: 253 | K33: 18 | L33: 13 | M33: 2 | N33: =SUM(J33:M33) | O33: ='详细数据'!J165 | P33: =O33/N33 | Q33: 产品力 | R33: 站点巴士 | T33: =IF(N33="","",IF(N33>=500000,"S 级",IF(N33>=100000,"A 级",IF(N33>=50000,"B 级","C 级"))))
A34: 46129 | B34: =A34+7 | C34: 无法投放 | D34: 楚楚爱济宁 | E34: https://www.douyin.com/video/7629612388421693945 | G34: 滴滴站点巴士 🚌 它来啦～#嘉祥 #济宁 #滴滴站点巴士 #方便又实用 #出行 | H34: 950 | N34: =SUM(J34:M34) | P34: =O34/N34
A35: 46128 | B35: =A35+7 | C35: 投放完毕 | D35: 悠悠的视界 | E35: https://www.douyin.com/video/7629126711086685289 | F35: 2026/4/20投放1000元 | G35: 武汉人去黄石也太方便了吧，黄石首条滴滴站点巴士线路要来了，黄石往返武汉线路将于4月16日正式通车，往返双向车票黄石至武昌线路限时体验价14.9元起#黄石到武汉 #滴滴站点巴士 #黄石出行 #武汉通勤 #城际出行 | H35: 2031 | I35: ='详细数据'!AC164 | J35: 970 | K35: 280 | L35: 171 | M35: 1006 | N35: =SUM(J35:M35) | O35: ='详细数据'!J164 | P35: =O35/N35 | Q35: 产品力 | R35: 站点巴士 | T35: =IF(N35="","",IF(N35>=500000,"S 级",IF(N35>=100000,"A 级",IF(N35>=50000,"B 级","C 级"))))
A36: 46127 | B36: =A36+7 | C36: 无法投放 | D36: 叶同学 | E36: https://www.douyin.com/video/7628801934065316517 | G36: 厦门龙海往返出行的神仙级路线开了！滴巴上线啦！提前购票只要9.9，真的很划算#龙海厦门 #龙海巴士 #漳州交通 #跨城上班 #周末回家省钱攻略 | H36: 2636 | N36: =SUM(J36:M36) | P36: =O36/N36
A37: 46132 | B37: =A37+7 | C37: 投放完毕 | D37: 年年 | E37: https://www.douyin.com/video/7630833058359450441 | F37: 2026/4/22投放1000元 | G37: 岳阳的滴滴司机这么有节目的吗？！听爽了！！#GAI #功夫胖 #山歌王 | H37: 82 | I37: ='详细数据'!AC174 | J37: 1266 | K37: 47 | L37: 53 | M37: 95 | N37: =SUM(J37:M37) | O37: ='详细数据'!J174 | P37: =O37/N37 | Q37: 司机 | R37: 司乘互动 | T37: =IF(N37="","",IF(N37>=500000,"S 级",IF(N37>=100000,"A 级",IF(N37>=50000,"B 级","C 级"))))
A38: 46133 | B38: =A38+7 | C38: 投放完毕 | D38: 余梦似海 | E38: https://www.douyin.com/video/7631145389820062201 | F38: 2026/4/22投放1000元 | G38: 姐妹们！高德打车跟滴滴打车是有区别的你们知道吗？高德打车是出租车公司直接给你选择路线，就是大家都懂的，绕圈子路线，他不是按照最近路线给你选，滴滴打车是可以自己选路线的，我分享出来让不懂的姐妹打车出租车意避坑##出行 #出租车 #高德打车 #注意避坑#记录真实生活 | H38: 101 | I38: ='详细数据'!AC173 | J38: 330 | K38: 42 | L38: 73 | M38: 4 | N38: =SUM(J38:M38) | O38: ='详细数据'!J173 | P38: =O38/N38 | Q38: 无匹配类别 | R38: 无匹配类别 | T38: =IF(N38="","",IF(N38>=500000,"S 级",IF(N38>=100000,"A 级",IF(N38>=50000,"B 级","C 级"))))
A39: 46133 | B39: =A39+7 | C39: 投放完毕 | D39: 养森不能碰—第11年 | E39: https://www.douyin.com/video/7631151287887270757 | F39: 2026/4/22投放1000元 | G39: #记录我的生活 又回老家彭山了 | H39: 112 | I39: ='详细数据'!AC172 | J39: 685 | K39: 40 | L39: 60 | M39: 179 | N39: =SUM(J39:M39) | O39: ='详细数据'!J172 | P39: =O39/N39 | Q39: 场景 | R39: 跨城出行 | T39: =IF(N39="","",IF(N39>=500000,"S 级",IF(N39>=100000,"A 级",IF(N39>=50000,"B 级","C 级"))))
A40: 46133 | B40: =A40+7 | C40: 投放完毕 | D40: 清泉~漂荷 | E40: https://www.douyin.com/video/7631159721408326771 | F40: 2026/4/23投放1000元 | G40: 🚗这滴滴师傅也太会了吧！导航屏前插满鲜花💐瞬间治愈所有疲惫～生活美学不分职业！#车载小确幸 #美来自生活 | H40: 83 | I40: ='详细数据'!AC178 | J40: 1552 | K40: 63 | L40: 60 | M40: 10 | N40: =SUM(J40:M40) | O40: ='详细数据'!J178 | P40: =O40/N40 | Q40: 车内 | R40: 司机自发装置 | T40: =IF(N40="","",IF(N40>=500000,"S 级",IF(N40>=100000,"A 级",IF(N40>=50000,"B 级","C 级"))))
...

Sheet 5月加热汇总
A1: 发布日期 | B1: 投放截止日期 | C1: 状态 | D1: 达人名称 | E1: 链接 | F1: 投放记录 xx日投放xx元 | G1: 标题 | H1: 投前互动量 | I1: 投放互动量 | J1: 投放后点赞量 | K1: 投放后收藏量 | L1: 投放后评论量 | M1: 投放后转发量 | N1: 总互动量 | O1: 总投放金额 | P1: 综合cpe *投入/笔记外层互动数据 | Q1: 一级分类 | R1: 二级分类 | S1: 备注 | T1: 爆款定级
A2: 汇总 | H2: - | I2: - | N2: =SUM(N3:N70) | O2: =SUM(O3:O70) | P2: =O2/N2
A3: 46147 | B3: =A3+7 | C3: 投放完毕 | D3: 吴安芝 | E3: https://www.douyin.com/note/7636204932429437370 | F3: 2026/5/6投放1000元2026/5/7投放5000元 | G3: 我评论了@浮生 的作品：想起我之前夏天和朋友打车，朋友用的某地图打的一口价的车，司机就说，一口价的车没有空调服务司机还振振有词。我在某滴上打车，特惠也好特价也好，都有空调 | H3: 76 | I3: ='详细数据'!AC204+'详细数据'!AC206 | J3: 30000 | K3: 2718 | L3: 983 | M3: 379 | N3: =SUM(J3:M3) | O3: ='详细数据'!J204+'详细数据'!J206 | P3: =O3/N3 | Q3: 无匹配类别 | R3: 无匹配类别 | T3: =IF(N3="","",IF(N3>=500000,"S 级",IF(N3>=100000,"A 级",IF(N3>=50000,"B 级","C 级"))))
A4: 46146 | B4: =A4+7 | C4: 投放完毕 | D4: 秋恋雪 | E4: https://www.douyin.com/video/7636020034524274043 | F4: 2026/5/6投放1000元 | G4: 吹着长安街的晚风，邂逅天安门的夜色。遇到超暖心的滴滴师傅，细心放缓车速，成全每一份想定格盛世风景的心意。平凡人，最动人的温柔。#吃喝玩乐分享计划 #天安门 #北京夜景 #视觉冲击旅行 #视觉盛宴城市记忆 | H4: 131 | I4: ='详细数据'!AC203 | J4: 2440 | K4: 47 | L4: 225 | M4: 4 | N4: =SUM(J4:M4) | O4: ='详细数据'!J203 | P4: =O4/N4 | Q4: 产品力 | R4: 价格优惠 | T4: =IF(N4="","",IF(N4>=500000,"S 级",IF(N4>=100000,"A 级",IF(N4>=50000,"B 级","C 级"))))
A5: 46146 | B5: =A5+7 | C5: 投放完毕 | D5: 马超Aster | E5: https://www.douyin.com/video/7636040612411755802 | F5: 2026/5/6投放1000元2026/5/7投放5000元2026/5/8投放5000元 | G5: 负债百万的滴滴司机告诉我，要好好爱自己 #滴滴司机 #爱情 #爱自己 #生活 #陌生人的温暖 | H5: 16600 | I5: ='详细数据'!AC202+'详细数据'!AC205+'详细数据'!AC209 | J5: 96000 | K5: 23000 | L5: 3860 | M5: 20000 | N5: =SUM(J5:M5) | O5: ='详细数据'!J202+'详细数据'!J205+'详细数据'!J209 | P5: =O5/N5 | Q5: 司机 | R5: 司乘温暖 | T5: =IF(N5="","",IF(N5>=500000,"S 级",IF(N5>=100000,"A 级",IF(N5>=50000,"B 级","C 级"))))
A6: 46145 | B6: =A6+7 | C6: 投放完毕 | D6: 寻找薇薇安·迈尔🎈 | E6: https://www.douyin.com/note/7635545727879850313 | F6: 2026/5/6投放1000元 | G6: 滴滴的后座上，藏着一个被羽绒服裹得严严实实的小朋友。 | H6: 86 | I6: ='详细数据'!AC201 | J6: 949 | K6: 11 | L6: 19 | M6: 14 | N6: =SUM(J6:M6) | O6: ='详细数据'!J201 | P6: =O6/N6 | Q6: 司机 | R6: 司乘互动 | T6: =IF(N6="","",IF(N6>=500000,"S 级",IF(N6>=100000,"A 级",IF(N6>=50000,"B 级","C 级"))))
A7: 46146 | B7: =A7+7 | C7: 投放完毕 | D7: 爱吃鱼的猫猫 | E7: https://www.douyin.com/note/7635922915368283775 | F7: 2026/5/6投放1000元 | G7: 常熟市区新推出的滴滴公交，体验了一把。3元/人，随叫随到。#常熟#公交出行绿色低碳 #公交乘车体验 #公共交通 | H7: 16 | I7: ='详细数据'!AC200 | J7: 747 | K7: 31 | L7: 41 | M7: 10 | N7: =SUM(J7:M7) | O7: ='详细数据'!J200 | P7: =O7/N7 | Q7: 场景 | R7: 家庭出行/带娃 | T7: =IF(N7="","",IF(N7>=500000,"S 级",IF(N7>=100000,"A 级",IF(N7>=50000,"B 级","C 级"))))
A8: 46145 | B8: =A8+7 | C8: 投放完毕 | D8: Daniel_花木吴彦祖 | E8: https://www.douyin.com/video/7635684064943428729 | F8: 2026/5/6投放1000元 | G8: #公共交通 #巴士 人多出行的正确打开方式哦 | H8: 12 | I8: ='详细数据'!AC199 | J8: 1152 | K8: 36 | L8: 138 | M8: 13 | N8: =SUM(J8:M8) | O8: ='详细数据'!J199 | P8: =O8/N8 | Q8: 产品力 | R8: 网约公交 | T8: =IF(N8="","",IF(N8>=500000,"S 级",IF(N8>=100000,"A 级",IF(N8>=50000,"B 级","C 级"))))
A9: 46148 | B9: =A9+7 | C9: 无法投放 | D9: 古城金街艾美女鞋馆主理人（夏款 | E9: https://www.douyin.com/video/7636439919821352357 | F9: 2026/5/6投放1000元 | G9: 今天因为我一个错误的决定，让我的宝贝儿子受累了，五一小长假结束，今天儿子返校去南昌坐高铁，本来他打算下午去名优特汽车站坐客车去南昌，然后我说帮他叫江南出行的车子，这种车子坐着舒服一些 | H9: 138 | Q9: 产品力 | R9: 站点巴士
A10: 46146 | B10: =A10+7 | C10: 投放完毕 | D10: 常熟热心姚阿姨 | E10: https://www.douyin.com/video/7636034872154967707 | F10: 2026/5/6投放1000元 | G10: 滴滴小公交小可爱送我回家啦 | H10: 7 | I10: ='详细数据'!AC198 | J10: 423 | K10: 13 | L10: 8 | M10: 9 | N10: =SUM(J10:M10) | O10: ='详细数据'!J198 | P10: =O10/N10 | Q10: 场景 | R10: 跨城出行 | T10: =IF(N10="","",IF(N10>=500000,"S 级",IF(N10>=100000,"A 级",IF(N10>=50000,"B 级","C 级"))))
A11: 46149 | B11: =A11+7 | C11: 投放完毕 | D11: 萬家幺女万和香 | E11: https://www.douyin.com/video/7636826521273382309 | F11: 2026/5/7投放1000元 | G11: 今天坐滴滴车，师傅问我在哪里下单？我说在微信里面，他说怎么坐车的全部都是美女坐我的车？我说那你走桃花运了，他说美女，你气质太好，我说你也长得很帅，到底是他犯花痴，还是我犯花痴？都夸对方长得帅，其实夸对方帅也是一种礼貌 | H11: 108 | I11: ='详细数据'!AC208 | J11: 259 | K11: 11 | L11: 12 | M11: 17 | N11: =SUM(J11:M11) | O11: ='详细数据'!J208 | P11: =O11/N11 | Q11: 产品力 | R11: 滴滴小巴 | T11: =IF(N11="","",IF(N11>=500000,"S 级",IF(N11>=100000,"A 级",IF(N11>=50000,"B 级","C 级"))))
A12: 46149 | B12: =A12+7 | C12: 投放完毕 | D12: 克莱因蓝 | E12: https://www.douyin.com/video/7637044455720278251 | F12: 2026/5/7投放1000元 | G12: 现在滴滴瞬间都这么有品吗！#打车#出租车司机 | H12: 2 | I12: ='详细数据'!AC207 | J12: 768 | K12: 65 | L12: 10 | M12: 17 | N12: =SUM(J12:M12) | O12: ='详细数据'!J207 | P12: =O12/N12 | Q12: 司机 | R12: 司乘互动 | T12: =IF(N12="","",IF(N12>=500000,"S 级",IF(N12>=100000,"A 级",IF(N12>=50000,"B 级","C 级"))))
A13: 46148 | B13: =A13+7 | C13: 投放完毕 | D13: 吉玺 | E13: https://www.douyin.com/video/7636643841961216127 | F13: 2026/5/8投放1000元 | G13: 家长是孩子的首任老师。现在只要有人对我们释放善意，孩子都会有感恩之心。比如昨天的滴滴司机，态度友善，还一路畅聊临下车我习惯性说了一声：“谢谢”！师傅立马说：期待下次还接你的订单，慢走！孩儿在旁边说：妈妈，给师傅一个好评吧，好评多了他的订单会多。 | H13: 72 | I13: ='详细数据'!AC210 | J13: 778 | K13: 28 | L13: 31 | M13: 5 | N13: =SUM(J13:M13) | O13: ='详细数据'!J210 | P13: =O13/N13 | Q13: 车内 | R13: 司机自发装置 | T13: =IF(N13="","",IF(N13>=500000,"S 级",IF(N13>=100000,"A 级",IF(N13>=50000,"B 级","C 级"))))
A14: 46150 | B14: =A14+7 | C14: 投放完毕 | D14: 弦外故事 | E14: https://www.douyin.com/video/7637394139268615462 | F14: 2026/5/9投放1000元 | G14: 刷爆朋友圈！谁能猜到网约车后座是歌神陈奕迅打车偶遇歌迷沉浸式听歌Eason忍不住开口跟唱恶搞司机网友：滴滴现在还缺人么？ #陈奕迅 #唱歌 #明星 #删了她 | H14: 98 | I14: ='详细数据'!AC211 | J14: 468 | K14: 27 | L14: 28 | M14: 34 | N14: =SUM(J14:M14) | O14: ='详细数据'!J211 | P14: =O14/N14 | Q14: 司机 | R14: 司机服务 | T14: =IF(N14="","",IF(N14>=500000,"S 级",IF(N14>=100000,"A 级",IF(N14>=50000,"B 级","C 级"))))
A15: 46151 | B15: =A15+7 | C15: 无法投放 | D15: 豫S✨老梅👵🌟💫 | E15: https://www.douyin.com/video/7637703323614063275 | G15: 滴滴出行 喜欢打女司机的车 | H15: 119 | Q15: 司机 | R15: 司乘互动
A16: 46152 | B16: =A16+7 | C16: 投放完毕 | D16: 漫寻星📸. | E16: https://www.douyin.com/video/7637869144147080817 | F16: 2026/5/11投放1000元 | G16: 常熟这个不起眼的小城市，却有着网约公交😍不仅覆盖了部分公交线网空白，还方便了市民出行，别看车小，却总能跑出最快的时速，试运营期间，只需3元/人次，就能开启这段美妙旅程，非常有性价比🤓#公交车 #公交迷 #公共交通 #城市公交 #网约公交 | H16: 88 | I16: ='详细数据'!AC212 | J16: 2765 | K16: 57 | L16: 17 | M16: 52 | N16: =SUM(J16:M16) | O16: ='详细数据'!J212 | P16: =O16/N16 | Q16: 司机 | R16: 女司机 | T16: =IF(N16="","",IF(N16>=500000,"S 级",IF(N16>=100000,"A 级",IF(N16>=50000,"B 级","C 级"))))
A17: 46154 | B17: =A17+7 | C17: 无法投放 | D17: 蘅若 | E17: https://www.douyin.com/note/7638835615421411577 | G17: 是不是南方的滴滴司机都帮忙拿行李呀，莫名的感觉很好 | H17: 130 | Q17: 产品力 | R17: 网约公交
A18: 46153 | B18: =A18+7 | C18: 投放完毕 | D18: 徐伟华 | E18: https://www.douyin.com/note/7638470477203931643 | F18: 2026/5/13投放1000元 | G18: 出发啦！今天滴滴车司机是我的老乡，车内非常整洁！给他点赞！ | H18: 73 | I18: ='详细数据'!AC213 | J18: 102 | K18: 5 | L18: 10 | M18: 5 | N18: =SUM(J18:M18) | O18: ='详细数据'!J213 | P18: =O18/N18 | Q18: 司机 | R18: 司机服务 | T18: =IF(N18="","",IF(N18>=500000,"S 级",IF(N18>=100000,"A 级",IF(N18>=50000,"B 级","C 级"))))
A19: 46155 | B19: =A19+7 | C19: 投放完毕 | D19: 宋疯恩🐌🦋 | E19: https://www.douyin.com/note/7639298762268064241 | F19: 2026/5/15投放1000元 | G19: 我只敢在这个车里全程专心看手机 并且心里不会对路况感到担惊害怕#滴滴专车 | H19: 142 | I19: ='详细数据'!AC221 | J19: 1061 | K19: 14 | L19: 148 | M19: 10 | N19: =SUM(J19:M19) | O19: ='详细数据'!J221 | P19: =O19/N19 | Q19: 车内 | R19: 车内整洁 | T19: =IF(N19="","",IF(N19>=500000,"S 级",IF(N19>=100000,"A 级",IF(N19>=50000,"B 级","C 级"))))
A20: 46155 | B20: =A20+7 | C20: 投放完毕 | D20: 小六liu | E20: https://www.douyin.com/note/7639360447649575034 | F20: 2026/5/15投放1000元 | G20: 我将拥护滴滴打车#如何选择真正的靠谱平台 #女性安全 #滴滴出行 | H20: 248 | I20: ='详细数据'!AC220 | J20: 931 | K20: 22 | L20: 348 | M20: 77 | N20: =SUM(J20:M20) | O20: ='详细数据'!J220 | P20: =O20/N20 | Q20: 产品力 | R20: 专车/豪华车 | T20: =IF(N20="","",IF(N20>=500000,"S 级",IF(N20>=100000,"A 级",IF(N20>=50000,"B 级","C 级"))))
A21: 46156 | B21: =A21+7 | C21: 投放完毕 | D21: 美美姐🇨🇳🇭🇰 | E21: https://www.douyin.com/note/7639587991471701105 | F21: 2026/5/15投放1000元 | G21: 5月12晚上我们在聚会回家叫的滴滴下车时把手机忘在了车上，回到家后大概半二十分钟左右发现手机不在， | H21: 88 | I21: ='详细数据'!AC219 | J21: 291 | K21: 6 | L21: 7 | M21: 7 | N21: =SUM(J21:M21) | O21: ='详细数据'!J219 | P21: =O21/N21 | Q21: 产品力 | R21: 女性友好计划 | T21: =IF(N21="","",IF(N21>=500000,"S 级",IF(N21>=100000,"A 级",IF(N21>=50000,"B 级","C 级"))))
A22: 46154 | B22: =A22+7 | C22: 投放完毕 | D22: 骑境•路飞 | E22: https://www.douyin.com/note/7638908016368917681 | F22: 2026/5/15投放1000元 | G22: 外胎爆了怎么办？ #扎胎了怎么办 #货拉拉 | H22: 74 | I22: ='详细数据'!AC215 | J22: 880 | K22: 19 | L22: 42 | M22: 3 | N22: =SUM(J22:M22) | O22: ='详细数据'!J215 | P22: =O22/N22 | Q22: 司机 | R22: 失物返还 | T22: =IF(N22="","",IF(N22>=500000,"S 级",IF(N22>=100000,"A 级",IF(N22>=50000,"B 级","C 级"))))
A23: 46156 | B23: =A23+7 | C23: 投放完毕 | D23: 婷宝儿💖 | E23: https://www.douyin.com/video/7639539369804821434 | F23: 2026/5/15投放1000元 | G23: 平时上班打了这么多滴滴，第一次遇到这么干净又帅气的司机！坐起心情都要舒畅些 | H23: 149 | I23: ='详细数据'!AC218 | J23: 342 | K23: 31 | L23: 19 | M23: 16 | N23: =SUM(J23:M23) | O23: ='详细数据'!J218 | P23: =O23/N23 | Q23: 无匹配类别 | R23: 无匹配类别 | T23: =IF(N23="","",IF(N23>=500000,"S 级",IF(N23>=100000,"A 级",IF(N23>=50000,"B 级","C 级"))))
A24: 46156 | B24: =A24+7 | C24: 投放完毕 | D24: 幕兮彤 | E24: https://www.douyin.com/note/7639700717046112383 | F24: 2026/5/15投放1000元 | G24: 好可爱#拼车趣事 #滴滴司机 | H24: 87 | I24: ='详细数据'!AC217 | J24: 421 | K24: 4 | L24: 7 | M24: 12 | N24: =SUM(J24:M24) | O24: ='详细数据'!J217 | P24: =O24/N24 | Q24: 司机 | R24: 司机服务 | T24: =IF(N24="","",IF(N24>=500000,"S 级",IF(N24>=100000,"A 级",IF(N24>=50000,"B 级","C 级"))))
A25: 46156 | B25: =A25+7 | C25: 投放完毕 | D25: 不吃韭菜~ | E25: https://www.douyin.com/note/7639772595369289381 | F25: 2026/5/15投放1000元 | G25: 第一次打到聋哑司机的车 | H25: 188 | I25: ='详细数据'!AC216 | J25: 3951 | K25: 56 | L25: 69 | M25: 38 | N25: =SUM(J25:M25) | O25: ='详细数据'!J216 | P25: =O25/N25 | Q25: 产品力 | R25: 拼车 | T25: =IF(N25="","",IF(N25>=500000,"S 级",IF(N25>=100000,"A 级",IF(N25>=50000,"B 级","C 级"))))
A26: 46157 | B26: =A26+7 | C26: 投放完毕 | D26: 艾米 | E26: https://www.douyin.com/note/7640081270203342562 | F26: 2026/5/18投放1000元 | G26: 咱也赶个时髦，头一次搭滴滴，还是个美女 | H26: 111 | I26: ='详细数据'!AC226 | J26: 669 | K26: 28 | L26: 41 | M26: 26 | N26: =SUM(J26:M26) | O26: ='详细数据'!J226 | P26: =O26/N26 | Q26: 司机 | R26: 特殊身份-听障司机 | T26: =IF(N26="","",IF(N26>=500000,"S 级",IF(N26>=100000,"A 级",IF(N26>=50000,"B 级","C 级"))))
A27: 46158 | B27: =A27+7 | C27: 投放完毕 | D27: 逢时春迟月 | E27: https://www.douyin.com/note/7640285558464104890 | F27: 2026/5/18投放1000元2026/5/19投放5000元 | G27: #特斯拉 上班打车打到特斯拉车主，开始以为我眼花了，我上车之后问叔叔，你 | H27: 3430 | I27: ='详细数据'!AC225+'详细数据'!AC227 | J27: 18000 | K27: 264 | L27: 3065 | M27: 1114 | N27: =SUM(J27:M27) | O27: ='详细数据'!J225+'详细数据'!J227 | P27: =O27/N27 | Q27: 司机 | R27: 女司机 | T27: =IF(N27="","",IF(N27>=500000,"S 级",IF(N27>=100000,"A 级",IF(N27>=50000,"B 级","C 级"))))
A28: 46157 | B28: =A28+7 | C28: 投放完毕 | D28: 小贝勒爷 | E28: https://www.douyin.com/note/7640097613844477669 | F28: 2026/5/18投放1000元 | G28: 敬礼～安全感爆棚。打到中共党员师傅的车🚗安 | H28: 742 | I28: ='详细数据'!AC224 | J28: 1075 | K28: 45 | L28: 176 | M28: 258 | N28: =SUM(J28:M28) | O28: ='详细数据'!J224 | P28: =O28/N28 | Q28: 车内 | R28: 特殊车型/车衣 | T28: =IF(N28="","",IF(N28>=500000,"S 级",IF(N28>=100000,"A 级",IF(N28>=50000,"B 级","C 级"))))
A29: 46159 | B29: =A29+7 | C29: 投放完毕 | D29: FM101.6小仙 | E29: https://www.douyin.com/video/7640775971604485993 | F29: 2026/5/18投放1000元 | G29: 和奶奶出门叫了个滴滴、师傅很热情，长得也挺帅，一路上聊的也挺嗨，结果奶奶拉着脸开始教育我，说我不要忘了自己结婚了，有老公还这样，说我不考虑孩子 | H29: 481 | I29: ='详细数据'!AC223 | J29: 1357 | K29: 30 | L29: 59 | M29: 491 | N29: =SUM(J29:M29) | O29: ='详细数据'!J223 | P29: =O29/N29 | Q29: 司机 | R29: 司机服务 | T29: =IF(N29="","",IF(N29>=500000,"S 级",IF(N29>=100000,"A 级",IF(N29>=50000,"B 级","C 级"))))
A30: 46159 | B30: =A30+7 | C30: 投放完毕 | D30: 十亿少男的梦94 | E30: https://www.douyin.com/video/7640834357934858225 | F30: 2026/5/18投放1000元 | G30: 宝宝巴士🚌 #新能源城市公交 #网约公交车谁懂啊！坐网约公交🚍有种坐宝宝巴士的快乐🎉 | H30: 48 | I30: ='详细数据'!AC222 | J30: 1045 | K30: 51 | L30: 47 | M30: 61 | N30: =SUM(J30:M30) | O30: ='详细数据'!J222 | P30: =O30/N30 | Q30: 场景 | R30: 带长辈出行 | T30: =IF(N30="","",IF(N30>=500000,"S 级",IF(N30>=100000,"A 级",IF(N30>=50000,"B 级","C 级"))))
A31: 46160 | B31: =A31+7 | C31: 投放完毕 | D31: 沧桑大叔 | E31: https://www.douyin.com/video/7641120212301335651 | F31: 2026/5/19投放1000元 | G31: 【鲁BA29065】人啊一生能遇多少善良的人？感谢临沂好大哥滴滴出行夜班司机冒雨上百里地从胶州给我送回失物！！！#感谢好人一生平安 #两个龙虾🦞店为丁大哥终身免费吃#青岛好司机鲁BA29065 | H31: 198 | I31: ='详细数据'!AC232 | J31: 1330 | K31: 33 | L31: 80 | M31: 6 | N31: =SUM(J31:M31) | O31: ='详细数据'!J232 | P31: =O31/N31 | Q31: 产品力 | R31: 网约公交 | T31: =IF(N31="","",IF(N31>=500000,"S 级",IF(N31>=100000,"A 级",IF(N31>=50000,"B 级","C 级"))))
A32: 46160 | B32: =A32+7 | C32: 投放完毕 | D32: 吃完芒果早点睡觉 | E32: https://www.douyin.com/note/7640942718125977999 | F32: 2026/5/19投放1000元 | G32: “人们常以缘分深厚作为亲近的借口，而以无缘，作为了却情谊的假辞而已，或许有一天真到了无路可去无法可解的地步， | H32: 95 | I32: ='详细数据'!AC231 | J32: 1662 | K32: 29 | L32: 100 | M32: 38 | N32: =SUM(J32:M32) | O32: ='详细数据'!J231 | P32: =O32/N32 | Q32: 司机 | R32: 失物返还 | T32: =IF(N32="","",IF(N32>=500000,"S 级",IF(N32>=100000,"A 级",IF(N32>=50000,"B 级","C 级"))))
A33: 46160 | B33: =A33+7 | C33: 投放完毕 | D33: 丹哥🌈 | E33: https://www.douyin.com/video/7640897437604151503 | F33: 2026/5/19投放1000元 | G33: 久了没打车，滴滴都是宝马#滴滴出行 | H33: 77 | I33: ='详细数据'!AC230 | J33: 143 | K33: 4 | L33: 65 | M33: 7 | N33: =SUM(J33:M33) | O33: ='详细数据'!J230 | P33: =O33/N33 | Q33: 无匹配类别 | R33: 无匹配类别 | T33: =IF(N33="","",IF(N33>=500000,"S 级",IF(N33>=100000,"A 级",IF(N33>=50000,"B 级","C 级"))))
A34: 46159 | B34: =A34+7 | C34: 投放完毕 | D34: 晓雅姐 | E34: https://www.douyin.com/note/7640813564869112942 | F34: 2026/5/19投放1000元 | G34: 遇到好的司机真的是一种幸运，说话语气温和给人一种温暖，穿戴整齐干净 | H34: 198 | I34: ='详细数据'!AC229 | J34: 1331 | K34: 29 | L34: 68 | M34: 12 | N34: =SUM(J34:M34) | O34: ='详细数据'!J229 | P34: =O34/N34 | Q34: 车内 | R34: 特殊车型/车衣 | T34: =IF(N34="","",IF(N34>=500000,"S 级",IF(N34>=100000,"A 级",IF(N34>=50000,"B 级","C 级"))))
A35: 46160 | B35: =A35+7 | C35: 投放完毕 | D35: 物是人非yaa(没回复就 | E35: https://www.douyin.com/note/7641163045289481322 | F35: 2026/5/19投放1000元 | G35: #北川地震遗址2026年5月18日，绵阳安州区，天气暖和也不闷热。打了一辆滴滴 | H35: 88 | I35: ='详细数据'!AC228 | J35: 1591 | K35: 47 | L35: 43 | M35: 19 | N35: =SUM(J35:M35) | O35: ='详细数据'!J228 | P35: =O35/N35 | Q35: 司机 | R35: 司机服务 | T35: =IF(N35="","",IF(N35>=500000,"S 级",IF(N35>=100000,"A 级",IF(N35>=50000,"B 级","C 级"))))
A36: 46162 | B36: =A36+7 | C36: 投放完毕 | D36: 晓雅姐 | E36: https://www.douyin.com/note/7641875385806374833 | F36: 2026/5/22投放1000元 | G36: #专车接送 #出行 普通的520的下午，普通的小雅女士穿了很喜欢的牛仔鱼尾裙，化了个淡妆 | H36: 84 | I36: ='详细数据'!AC239 | J36: 191 | K36: 10 | L36: 16 | M36: 4 | N36: =SUM(J36:M36) | O36: ='详细数据'!J239 | P36: =O36/N36 | Q36: 场景 | R36: 旅游出行 | T36: =IF(N36="","",IF(N36>=500000,"S 级",IF(N36>=100000,"A 级",IF(N36>=50000,"B 级","C 级"))))
A37: 46162 | B37: =A37+7 | C37: 投放完毕 | D37: 安安💓 | E37: https://www.douyin.com/video/7641882679970377957 | F37: 2026/5/22投放1000元 | G37: 今天回一趟汕尾，坐滴滴车都感觉滴滴很高档，这辈子没有坐过，，， | H37: 75 | I37: ='详细数据'!AC238 | J37: 421 | K37: 5 | L37: 21 | M37: 1 | N37: =SUM(J37:M37) | O37: ='详细数据'!J238 | P37: =O37/N37 | Q37: 产品力 | R37: 专车/豪华车 | T37: =IF(N37="","",IF(N37>=500000,"S 级",IF(N37>=100000,"A 级",IF(N37>=50000,"B 级","C 级"))))
A38: 46162 | B38: =A38+7 | C38: 投放完毕 | D38: SSKYLAR | E38: https://www.douyin.com/note/7641993475752266235 | F38: 2026/5/22投放1000元 | G38: 上班楠 #原相机乘乘的 今天的开心是因为滴滴司机巨帅啊啊啊啊啊啊啊啊那我自己自拍这么多张沙意思？ | H38: 109 | I38: ='详细数据'!AC237 | J38: 766 | K38: 13 | L38: 38 | M38: 21 | N38: =SUM(J38:M38) | O38: ='详细数据'!J237 | P38: =O38/N38 | Q38: 产品力 | R38: 专车/豪华车 | T38: =IF(N38="","",IF(N38>=500000,"S 级",IF(N38>=100000,"A 级",IF(N38>=50000,"B 级","C 级"))))
A39: 46162 | B39: =A39+7 | C39: 投放完毕 | D39: @五月💘🌹 | E39: https://www.douyin.com/video/7641921320654050427 | F39: 2026/5/22投放1000元 | G39: 滴滴车司机清唱的真好听😄#520 | H39: 167 | I39: ='详细数据'!AC236 | J39: 370 | K39: 8 | L39: 11 | M39: 4 | N39: =SUM(J39:M39) | O39: ='详细数据'!J236 | P39: =O39/N39 | Q39: 司机 | R39: 司乘互动 | T39: =IF(N39="","",IF(N39>=500000,"S 级",IF(N39>=100000,"A 级",IF(N39>=50000,"B 级","C 级"))))
A40: 46162 | B40: =A40+7 | C40: 投放完毕 | D40: 小绿绿绿📸 | E40: https://www.douyin.com/video/7641922307711110454 | F40: 2026/5/22投放1000元2026/5/26投放30000元 | G40: 有一种爱叫妈妈永远在#亲情#家的味道#人间观察计划 | H40: 78302 | I40: ='详细数据'!AC235+'详细数据'!AC242 | J40: 232000 | K40: 16000 | L40: 9946 | M40: 16000 | N40: =SUM(J40:M40) | O40: ='详细数据'!J235+'详细数据'!J242 | P40: =O40/N40 | Q40: 司机 | R40: 司乘互动 | T40: =IF(N40="","",IF(N40>=500000,"S 级",IF(N40>=100000,"A 级",IF(N40>=50000,"B 级","C 级"))))
...

Sheet 6月加热汇总
A1: 发布日期 | B1: 投放截止日期 | C1: 状态 | D1: 达人名称 | E1: 链接 | F1: 投放记录 xx日投放xx元 | G1: 标题 | H1: 投前互动量 | I1: 投放互动量 | J1: 投放后点赞量 | K1: 投放后收藏量 | L1: 投放后评论量 | M1: 投放后转发量 | N1: 总互动量 | O1: 总投放金额 | P1: 综合cpe *投入/笔记外层互动数据 | Q1: 一级分类 | R1: 二级分类
A2: 汇总 | H2: - | I2: - | N2: =SUM(N3:N70) | O2: =SUM(O3:O70) | P2: =O2/N2
A3: 46173 | B3: =A3+7 | C3: 投放完毕 | D3: 月嫂 苗苗 拒绝连赞 | E3: https://www.douyin.com/video/7645956165910827377 | F3: 2026/6/2投放1000元 | G3: 滴滴打车平台真给力还是女司机漂亮美女车坐着舒服出发上班去了#车外风景 | H3: 80 | I3: ='详细数据'!AC250 | J3: 554 | K3: 8 | L3: 34 | M3: 2 | N3: =SUM(J3:M3) | O3: ='详细数据'!J250 | P3: =O3/N3 | Q3: 司机 | R3: 女司机
A4: 46175 | B4: =A4+7 | C4: 投放完毕 | D4: 小幸运888 | E4: https://www.douyin.com/note/7646727972648596218 | F4: 2026/6/3投放1000元2026/6/4投放5000元 | G4: 凌晨两点，那个沉默的司机救了我一命 | H4: 2597 | I4: ='详细数据'!AC253+'详细数据'!AC258 | J4: 16000 | K4: 1311 | L4: 444 | M4: 231 | N4: =SUM(J4:M4) | O4: ='详细数据'!J253+'详细数据'!J258 | P4: =O4/N4 | Q4: 司机 | R4: 司乘温暖
A5: 46175 | B5: =A5+7 | C5: 投放完毕 | D5: 天天有钱花女士 | E5: https://www.douyin.com/note/7646701552317873787 | F5: 2026/6/3投放1000元 | G5: 滴滴打车。肯定是特别勤快又负责任的滴滴司机，接到我订单就立马过来了，结果我一看他衣服都穿反了😁，我该怎么不失礼貌又委婉的提醒他啊！在线等挺急的…#在线等 | H5: 95 | I5: ='详细数据'!AC254 | J5: 392 | K5: 19 | L5: 100 | M5: 15 | N5: =SUM(J5:M5) | O5: ='详细数据'!J254 | P5: =O5/N5 | Q5: 司机 | R5: 司乘互动
A6: 46175 | B6: =A6+7 | C6: 无法投放 | D6: 蛋炒西红柿加番茄酱(求关注 | E6: https://www.douyin.com/note/7646632021980156346 | G6: 滴滴小程序和软件是都可以选择女司机的!#滴滴司机 #滴滴 #女性 #女性智慧 #女性成长 | H6: 521 | Q6: 产品力 | R6: 女性友好计划
A7: 46177 | B7: =A7+7 | C7: 投放完毕 | D7: 七里 | E7: https://www.douyin.com/video/7647214379003431907 | F7: 2026/6/4投放1000元 | G7: 前几天从医院出来，打车回家。上车以后才发现司机不会说话，是一位听障朋友。更要命的是，我还把上车地点定错了。我手忙脚乱地比划着请他先靠边停，又掏出手机打字给他看，他始终很耐心，没有半点不耐烦。重新设好目的地后，车子稳稳地开了一路。 | H7: 219 | I7: ='详细数据'!AC256 | J7: 2173 | K7: 21 | L7: 18 | M7: 9 | N7: =SUM(J7:M7) | O7: ='详细数据'!J256 | P7: =O7/N7 | Q7: 司机 | R7: 特殊身份-听障司机
A8: 46175 | B8: =A8+7 | C8: 投放完毕 | D8: @悠游自在 | E8: https://www.douyin.com/user/MS4wLjABAAAAJT00acZ9BEt6-OB1zk6oV1GFf2azeh_kQhjcxcwY0X8k-_kXcxTTL2JwWJUF35x1?from_tab_name=main&modal_id=7646742373196733811 | F8: 2026/6/4投放1000元 | G8: 退休低成本快乐 #退休日常生活记录 #网约 #一日游玩 | H8: 171 | I8: ='详细数据'!AC255 | J8: 1016 | K8: 48 | L8: 125 | M8: 31 | N8: =SUM(J8:M8) | O8: ='详细数据'!J255 | P8: =O8/N8 | Q8: 产品力 | R8: 网约公交
A9: 46177 | B9: =A9+7 | C9: 投放完毕 | D9: @LiLi_ | E9: https://www.douyin.com/user/MS4wLjABAAAAuZvZ6VAA6cysm3VWXGSfj4yJnWGSOUFbZFAky1iC_1Q?from_tab_name=main&modal_id=7647513382476541541&vid=7647513382476541541 | F9: 2026/6/5投放1000元 | G9: 今天趁着好天气、打了一次滴滴公交车🚌还是很方便哒 #滴滴公交 #来晒一下手机实拍画质 | H9: 52 | I9: ='详细数据'!AC259 | J9: 383 | K9: 11 | L9: 31 | M9: 14 | N9: =SUM(J9:M9) | O9: ='详细数据'!J259 | P9: =O9/N9 | Q9: 产品力 | R9: 网约公交
A10: 46179 | B10: =A10+7 | C10: 投放完毕 | D10: 汪涛和导盲犬叮当 | E10: https://www.douyin.com/video/7648092654844692970 | F10: 2026/6/8投放1000元 | G10: 同时带两条导盲犬上车，偶遇热情大连司机，小小车程满是温暖 在大连旅顺行程结束，我带着导盲犬叮当和另一个盲人伙伴以及另一条导盲犬椰果和他的家人结伴，从酒店打滴滴前往附近地铁站。临走和同行的视障朋友挥手告别，相聚时间很短，下次见面不知什么时候，心里很舍不得。 路上碰到一位热心的滴滴司机，上车主动搀扶我们，帮忙把行李放进后备箱。开车途中，师傅不停夸赞两只导盲犬乖巧听话。闲聊时师傅说，之前一直以为培育一只导盲犬需要200万。 我们跟师傅解释，一只导盲犬选育、长年训练、考核上岗，整体成本在20万左右，师傅听完才了解实情。 到地铁站下车，师傅又贴心把行李从后备箱拿出来。 一趟短短的车程，实实在在感受到大连人的热心和善心，谢谢这位暖心司机，为大连点赞。 #导盲犬叮当 #滴滴出行 #大连 #无障碍出行 #青年创作者计划 | H10: 164 | I10: ='详细数据'!AC261 | J10: 1414 | K10: 48 | L10: 33 | M10: 5 | N10: =SUM(J10:M10) | O10: ='详细数据'!J261 | P10: =O10/N10 | Q10: 司机 | R10: 司乘互动
A11: 46178 | B11: =A11+7 | C11: 投放完毕 | D11: ❤️心安੭ﾞ | E11: https://www.douyin.com/note/7647815865568169295 | F11: 2026/6/8投放1000元 | G11: 9237极速赶车第一人 3点26的高铁3点02上的滴滴 司机帮我赶路程3点22下的滴滴到检票口已经停止检票了，怎么检票口的妹妹说还可以进 一路呼呲带喘的赶到了月台 此刻 高铁马上到金华了 我下车了 | H11: 267 | I11: ='详细数据'!AC260 | J11: 1742 | K11: 42 | L11: 47 | M11: 4 | N11: =SUM(J11:M11) | O11: ='详细数据'!J260 | P11: =O11/N11 | Q11: 司机 | R11: 司乘互动
A12: 46177 | B12: =A12+7 | C12: 投放完毕 | D12: 电气昊子 | E12: https://www.douyin.com/video/7647506813403365321 | F12: 2026/6/9投放3000元2026/6/10投放5000元 | G12: 算了，哈尔滨夏天14度的含金量，跟你们说不清楚#哈尔滨 #晚霞 #城市的夜晚 #城市风景 #城市建设 | I12: ='详细数据'!AC263+'详细数据'!AC265 | J12: 23000 | K12: 768 | L12: 842 | M12: 5532 | N12: =SUM(J12:M12) | O12: ='详细数据'!J263+'详细数据'!J265 | P12: =O12/N12 | Q12: 产品力 | R12: 网约公交
A13: 46181 | B13: =A13+7 | C13: 投放完毕 | D13: ​车厘子的子 | E13: https://www.douyin.com/video/7648887011160830180 | F13: 2026/6/9投放500元 | G13: 来大连这几天给我的感受就是“大连 你美” | I13: ='详细数据'!AC262 | J13: 562 | K13: 50 | L13: 29 | M13: 137 | N13: =SUM(J13:M13) | O13: ='详细数据'!J262 | P13: =O13/N13 | Q13: 产品力 | R13: 滴滴专车
A14: 46181 | B14: =A14+7 | C14: 投放完毕 | D14: 小小麻～🥕 | E14: https://www.douyin.com/video/7648840710867964325 | F14: 2026/6/10投放1000元 | G14: 苏州站赶高铁 苏州站9:54的车，9:17才上车，滴滴出行写的预计36分钟。跟师傅一说赶高铁，师傅就起飞了...全程DJ嘿喂狗嘿喂狗，最后9:44到苏州站了。22公里，36分钟的车程，27分钟就到了，提前了10分钟！！天上飞机，地上苏E！！#车上的那些事儿 #天上飞机地上苏e | H14: 759 | I14: ='详细数据'!AC264 | J14: 1236 | K14: 33 | L14: 420 | M14: 141 | N14: =SUM(J14:M14) | O14: ='详细数据'!J264 | P14: =O14/N14 | Q14: 司机 | R14: 驾驶技术
A15: 46179 | B15: =A15+7 | C15: 投放完毕 | D15: 苏二小姐 | E15: https://www.douyin.com/video/7648121194428425573 | F15: 2026/6/10投放1000元 | G15: #滴滴公交车 #公交网约车 网约公交车来了🎈 | H15: 1739 | I15: ='详细数据'!AC269 | J15: 2496 | K15: 95 | L15: 275 | M15: 879 | N15: =SUM(J15:M15) | O15: ='详细数据'!J269 | P15: =O15/N15 | Q15: 产品力 | R15: 网约公交
A16: 46180 | B16: =A16+7 | C16: 投放完毕 | D16: 大鹏嘚吧嘚 | E16: https://www.douyin.com/video/7648609080373822586 | F16: 2026/6/10投放1000元 | G16: 空调嘎嘎凉快，只需三块#网约公交车 #天津公交 | H16: 4091 | I16: ='详细数据'!AC268 | J16: 3271 | K16: 224 | L16: 667 | M16: 2321 | N16: =SUM(J16:M16) | O16: ='详细数据'!J268 | P16: =O16/N16 | Q16: 产品力 | R16: 网约公交
A17: 46181 | B17: =A17+7 | C17: 投放完毕 | D17: 🐳洁 | E17: https://www.douyin.com/video/7648943448107741682 | F17: 2026/6/10投放1000元 | G17: 体验济南网约公交车🚌体验感很好 #济南网约公交 #公共交通 #公共交通绿色出行 我也体验了一把网约公交的快乐，全程只需3元钱，送到指定位置，这趟车我包车啦哈哈😃绿色出行的快乐 | H17: 741 | I17: ='详细数据'!AC267 | J17: 1033 | K17: 71 | L17: 150 | M17: 529 | N17: =SUM(J17:M17) | O17: ='详细数据'!J267 | P17: =O17/N17 | Q17: 产品力 | R17: 网约公交
A18: 46182 | B18: =A18+7 | C18: 在投 | D18: 夏荷 | E18: https://www.douyin.com/note/7649063213564689138 | F18: 2026/6/10投放1000元 | G18: #湖大到家里的温暖滴滴之旅。今天上午从湖大打车回家，遇到一位超贴心的美女师傅！ | H18: 73 | I18: ='详细数据'!AC266 | J18: 326 | K18: 18 | L18: 7 | M18: 5 | N18: =SUM(J18:M18) | O18: ='详细数据'!J266 | P18: =O18/N18 | Q18: 司机 | R18: 女司机
A19: 46187 | B19: =A19+7 | D19: 高鹰汤哥🐉 | E19: https://www.douyin.com/video/7651087551021976177 | G19: #演唱会的正确打开方式 还好美好占据了世界的大多数！演唱会结束，上万人的打车现场，我们已经打了一个小时的滴滴，加价都没打到，让我们遇见了一位好心的南京滴滴大哥买免费到我们到酒店，送到酒店我们问师傅多少钱，滴滴大哥说：我们不谈钱，只说缘。被感动到了！南京^_^下次我们还来！ | H19: 433
A20: 46188 | B20: =A20+7 | D20: 开往拉萨的小火车🚄 | E20: https://www.douyin.com/video/7651235777007377787 | G20: 带娃体验天津网约公交✨ 今天带小朋友去坐了天津的滴滴网约公交车，小家伙全程新奇得不行，眼睛都亮了，一直手舞足蹈的，特别开心～想坐的有什么不明白的可以评论区咨询我哦，今天都跟司机师傅聊明白的啦😊 | H20: 45

Sheet 详细数据
A1: 订单号 | B1: 订单类型 | C1: 作者名称 | D1: 视频标题 | E1: 视频链接 | F1: 下单时间 | G1: 状态 | H1: 订单金额（元） | I1: 预算（元） | J1: 消耗（元） | K1: 投放目标 | L1: 转化量 | M1: 转化成本 | N1: 直播间展示量 | O1: 新增观众量 | P1: 新增粉丝量 | Q1: 直播评论量 | R1: 视频播放量 | S1: 5秒完播率 | T1: 视频点赞量 | U1: 视频评论量 | V1: 视频分享量 | W1: 主页浏览量 | X1: 粉丝量 | Y1: 付费金额 | Z1: 预计投放时长 | AA1: 定向详情 | AC1: 总互动
A2: 1858553019316387 | B2: 普通订单 | C2: 酸奶吐司 | D2: 广州的滴滴车也太可爱了吧！坐得心情都美美的#广州 #广州滴滴 | E2: https://www.douyin.com/video/7612207816275352497 | F2: 46083.851 | G2: 投放完成 | H2: 500 | I2: 500 | J2: 500 | K2: 点赞评论量 | L2: 30072 | M2: 16.63 | R2: 30072 | S2: 未获得授权 | T2: 2695 | U2: 10 | V2: 405 | W2: 40 | X2: 4 | Z2: 6.0 小时 | AA2: 系统智能投放 | AC2: =SUM(T2:V2)
A3: 1858553070969904 | B3: 普通订单 | C3: 尚雅求真 | D3: “滴滴”赞 ——写在滴滴打车两年之际 （2026年2月28日） 滴滴， 无处不有处处有； 滴滴， 无时不有时时有。 滴滴， 给不车者插上翅膀； 滴滴， 让不车族便利出行。 滴滴， 让我退而不休； 滴滴， 让我视野开阔。 滴滴， 让我天天穿梭灞桥未央之间； 滴滴， 让我日日架起两地教育桥梁。 滴滴， 也让我认识了诸多司机朋友； 滴滴， 更让我了解了许多人间冷暖。 滴滴师傅的“豁达”， 让我身心愉悦； 滴滴师傅的“坚韧”， 让我倍感钦佩。 滴滴， 车车干净， 人人礼貌， 让我欣喜； 滴滴， 一会儿“78”， 一会儿“33”， 也让困惑。 愿滴滴管理日益科学！ 为滴滴司机点赞加油！ | E3: https://www.douyin.com/video/7611743676641705295 | F3: 46083.851 | G3: 投放完成 | H3: 500 | I3: 500 | J3: 500 | K3: 点赞评论量 | L3: 26860 | M3: 18.62 | R3: 26860 | S3: 未获得授权 | T3: 1082 | U3: 12 | V3: 0 | W3: 51 | X3: 10 | Z3: 6.0 小时 | AA3: 系统智能投放 | AC3: =SUM(T3:V3)
A4: 1858553087987723 | B4: 普通订单 | C4: Mr 钟又离 | D4: 太酷了 男滴滴司机的公主车： 啥样生活都是经营出来的不是吗#温暖治愈 #人间烟火#滴滴司机 #非标准人生#清醒的选负责到底 | E4: https://www.douyin.com/video/7612244922887857787 | F4: 46083.851 | G4: 投放完成 | H4: 500 | I4: 500 | J4: 500 | K4: 点赞评论量 | L4: 26306 | M4: 19.01 | R4: 26306 | S4: 未获得授权 | T4: 1404 | U4: 14 | V4: 9 | W4: 43 | X4: 11 | Z4: 6.0 小时 | AA4: 系统智能投放 | AC4: =SUM(T4:V4)
A5: 1858553133359451 | B5: 普通订单 | C5: 白开水泡茶 | D5: 武汉下雨天，我打了辆滴滴准备回学校。车正常停在路口，我刚要上车，手里装东西的纸袋子突然破了，东西撒了一地。我赶紧跟司机师傅说清楚情况，问他车上有没有袋子借我用一下。他二话不说，直接拿了个黑色塑料袋给我，那个袋子是真结实，我用过最好用的黑袋子！更贴心的是，他还跟我说：“一个怕又破了，我给你两个套着用。”本来就是件小麻烦，被师傅这么一弄，瞬间觉得特别暖心。陌生人的这份细心，真的让人心里特别舒服。 我再也不用写“发烧后妈妈背我去医院”的作文了。 我再也不用写“下雨天妈妈给我送伞”的作文了。 我再也不用写“我不会做题，老师耐心教我”的作文了。 我再也不用写“我摔倒了，同学扶我起来”的作文了。 我再也不用写“妈妈深夜给我盖被子”的作文了。 我再也不用写“我生病了，爸爸连夜带我看病”的作文了。 那些小时候最常见、最经典的模仿感恩作文，我终于不用再写啦！我有自己的感恩作文了！ | E5: https://www.douyin.com/note/7612110532075037129 | F5: 46083.851 | G5: 投放完成 | H5: 500 | I5: 500 | J5: 500 | K5: 点赞评论量 | L5: 44155 | M5: 11.32 | R5: 44155 | S5: 未获得授权 | T5: 1266 | U5: 7 | V5: 7 | W5: 1001 | X5: 5 | Z5: 6.0 小时 | AA5: 系统智能投放 | AC5: =SUM(T5:V5)
A6: 1858553164085371 | B6: 普通订单 | C6: 清风✨ | D6: 小同志，磁场又弱了吧，是时候充电了 #天安门 #士兵突击 #滴滴司机 感谢北京的滴滴师傅，放慢车速让我们看天安门夜景 | E6: https://www.douyin.com/video/7612087271226903844 | F6: 46083.852 | G6: 投放完成 | H6: 500 | I6: 500 | J6: 500 | K6: 点赞评论量 | L6: 27016 | M6: 18.51 | R6: 27016 | S6: 未获得授权 | T6: 2808 | U6: 15 | V6: 48 | W6: 56 | X6: 2 | Z6: 6.0 小时 | AA6: 系统智能投放 | AC6: =SUM(T6:V6)
A7: 1858553189305434 | B7: 普通订单 | C7: 北辰 | D7: 爱心：爱的传递。这是我遇见的最暖心的滴滴司机师傅，太原的成师傅，车牌号晋AAA1715。车费只有9.4元，但是我享受的确是专车的待遇，甚至比专车还好。上车、下车成师傅都很热心的帮我搬行李，我的行李很重，但是成师傅一点也不介意。上车后，车上很干净，而且车上备有充电器，小垃圾桶，防晕车的塑料袋，一次性口罩，一次性雨衣，防止血糖低的糖，还有速效救心丸。我和成师傅说，你是我遇见最贴心的司机师傅，没有之一。成师傅说，希望能尽自己所能，帮助更多的人。给太原成师傅点赞，希望以后还能坐到您的车。 | E7: https://www.douyin.com/note/7611832044951303909 | F7: 46083.852 | G7: 投放完成 | H7: 500 | I7: 500 | J7: 500 | K7: 点赞评论量 | L7: 28147 | M7: 17.76 | R7: 28147 | S7: 未获得授权 | T7: 1058 | U7: 13 | V7: 2 | W7: 233 | X7: 13 | Z7: 6.0 小时 | AA7: 系统智能投放 | AC7: =SUM(T7:V7)
A8: 1858553218214055 | B8: 普通订单 | C8: 一生有你 | D8: 人生第一次打到滴滴女司机，技术稳得一批，完全不输男司机👍 | E8: https://www.douyin.com/note/7611432494563328113 | F8: 46083.853 | G8: 投放完成 | H8: 500 | I8: 500 | J8: 500 | K8: 点赞评论量 | L8: 27088 | M8: 18.46 | R8: 27088 | S8: 未获得授权 | T8: 1257 | U8: 31 | V8: 4 | W8: 208 | X8: 11 | Z8: 6.0 小时 | AA8: 系统智能投放 | AC8: =SUM(T8:V8)
A9: 1858553250777130 | B9: 普通订单 | C9: Saffron | D9: 下班遇到了一位温暖的滴滴司机，椅背贴了一张纸条，口袋里放了两本小册子，两支笔和一面镜子，出于好奇心翻开册子却得到了最温暖的慰藉。司机师傅说这是他很早就想做的事情，希望他的工作也能给每一位归家或旅途中的乘客带来温暖和治愈。看着每一个陌生人的留言感觉上班的疲惫和焦虑一扫而空，我原本寻思那些个互联网上所谓的世界美好的宣言都是空谈，但是到此时此刻一时一景一心境，一花一景一世界才得以具像化。感恩遇见这位温暖的师傅，也感谢每一位留言的陌生人给我带来的幸福感。愿无论是深陷囹圄还是已经拥抱幸福的你们未来的每一天都平安喜乐，万事顺遂！ | E9: https://www.douyin.com/note/7611499522330631857 | F9: 46083.853 | G9: 投放完成 | H9: 500 | I9: 500 | J9: 500 | K9: 点赞评论量 | L9: 24300 | M9: 20.58 | R9: 24300 | S9: 未获得授权 | T9: 1280 | U9: 12 | V9: 9 | W9: 50 | X9: 13 | Z9: 6.0 小时 | AA9: 系统智能投放 | AC9: =SUM(T9:V9)
